Workbook

Sheet Resumen
A1: Handover W35 vs W34 - Kylie MU
A2: Consensus - Final en unidades. Horizonte de foco: 2026.M09 a 2027.M04 (8 meses). W35 = CurrentWorkingView | W34 = Month-2026.M08.W34(Recovered) | LY = Consensus - Final LY M.
B4: HEADLINE
B5: Consensus - Final (u) | C5: LY | D5: W34 (ciclo pasado) | E5: W35 (este ciclo) | F5: Δ vs LC (u) | G5: Δ vs LC (%) | H5: Δ vs LY (u) | I5: Δ vs LY (%)
B6: Horizonte 2026.M09 - 2027.M04 | C6: =SUMIFS(Datos!$T$2:$T$94,Datos!$F$2:$F$94,1) -> 56438 | D6: =SUMIFS(Datos!$O$2:$O$94,Datos!$F$2:$F$94,1) -> 40721 | E6: =SUMIFS(Datos!$H$2:$H$94,Datos!$F$2:$F$94,1) -> 38682 | F6: =E6-D6 -> -2039 | G6: =IFERROR(E6/D6-1,"") -> -0.050072444 | H6: =E6-C6 -> -17756 | I6: =IFERROR(E6/C6-1,"") -> -0.31461072
B7: del cual: FY27 Q1 (Sep-26) | C7: =SUMIFS(Datos!$T$2:$T$94,Datos!$E$2:$E$94,"FY27 Q1",Datos!$F$2:$F$94,1) -> 5552 | D7: =SUMIFS(Datos!$O$2:$O$94,Datos!$E$2:$E$94,"FY27 Q1",Datos!$F$2:$F$94,1) -> 6409 | E7: =SUMIFS(Datos!$H$2:$H$94,Datos!$E$2:$E$94,"FY27 Q1",Datos!$F$2:$F$94,1) -> 7992 | F7: =E7-D7 -> 1583 | G7: =IFERROR(E7/D7-1,"") -> 0.24699641 | H7: =E7-C7 -> 2440 | I7: =IFERROR(E7/C7-1,"") -> 0.43948127
B8: del cual: FY27 Q2 (Oct-Dic 26) | C8: =SUMIFS(Datos!$T$2:$T$94,Datos!$E$2:$E$94,"FY27 Q2",Datos!$F$2:$F$94,1) -> 12831 | D8: =SUMIFS(Datos!$O$2:$O$94,Datos!$E$2:$E$94,"FY27 Q2",Datos!$F$2:$F$94,1) -> 14291 | E8: =SUMIFS(Datos!$H$2:$H$94,Datos!$E$2:$E$94,"FY27 Q2",Datos!$F$2:$F$94,1) -> 13982 | F8: =E8-D8 -> -309 | G8: =IFERROR(E8/D8-1,"") -> -0.021622 | H8: =E8-C8 -> 1151 | I8: =IFERROR(E8/C8-1,"") -> 0.089704622
B9: del cual: FY27 Q3 (Ene-Mar 27) | C9: =SUMIFS(Datos!$T$2:$T$94,Datos!$E$2:$E$94,"FY27 Q3",Datos!$F$2:$F$94,1) -> 34757 | D9: =SUMIFS(Datos!$O$2:$O$94,Datos!$E$2:$E$94,"FY27 Q3",Datos!$F$2:$F$94,1) -> 16184 | E9: =SUMIFS(Datos!$H$2:$H$94,Datos!$E$2:$E$94,"FY27 Q3",Datos!$F$2:$F$94,1) -> 14101 | F9: =E9-D9 -> -2083 | G9: =IFERROR(E9/D9-1,"") -> -0.12870737 | H9: =E9-C9 -> -20656 | I9: =IFERROR(E9/C9-1,"") -> -0.59429755
B10: del cual: FY27 Q4 (Abr-27) | C10: =SUMIFS(Datos!$T$2:$T$94,Datos!$E$2:$E$94,"FY27 Q4",Datos!$F$2:$F$94,1) -> 3298 | D10: =SUMIFS(Datos!$O$2:$O$94,Datos!$E$2:$E$94,"FY27 Q4",Datos!$F$2:$F$94,1) -> 3837 | E10: =SUMIFS(Datos!$H$2:$H$94,Datos!$E$2:$E$94,"FY27 Q4",Datos!$F$2:$F$94,1) -> 2607 | F10: =E10-D10 -> -1230 | G10: =IFERROR(E10/D10-1,"") -> -0.32056294 | H10: =E10-C10 -> -691 | I10: =IFERROR(E10/C10-1,"") -> -0.20952092
B12: Horizonte EXCLUYENDO 2027.M02 (mes distorsionado por el one-off de Feb-26) | C12: =SUMIFS(Datos!$T$2:$T$94,Datos!$D$2:$D$94,"<>2027.M02",Datos!$F$2:$F$94,1) -> 32849 | D12: =SUMIFS(Datos!$O$2:$O$94,Datos!$D$2:$D$94,"<>2027.M02",Datos!$F$2:$F$94,1) -> 35291 | E12: =SUMIFS(Datos!$H$2:$H$94,Datos!$D$2:$D$94,"<>2027.M02",Datos!$F$2:$F$94,1) -> 33568 | F12: =E12-D12 -> -1723 | G12: =IFERROR(E12/D12-1,"") -> -0.048822646 | H12: =E12-C12 -> 719 | I12: =IFERROR(E12/C12-1,"") -> 0.021888033
B15: BRIDGE W34 → W35 (horizonte M09-M04, unidades)
B16: Concepto | C16: Unidades | D16: Comentario
B17: W34 - Consensus ciclo pasado | D17: =SUMIFS(Datos!$O$2:$O$94,Datos!$F$2:$F$94,1) -> 40721 | E17: Punto de partida
B18: Δ System FC (lineas que usan el sistema) | D18: =SUMIFS(Datos!$I$2:$I$94,Datos!$G$2:$G$94,"Sistema",Datos!$F$2:$F$94,1)-SUMIFS(Datos!$P$2:$P$94,Datos!$G$2:$G$94,"Sistema",Datos!$F$2:$F$94,1) -> -2129 | E18: El motor estadistico bajo su propio numero
B19: Δ Reasonability Adjustment | D19: =SUMIFS(Datos!$J$2:$J$94,Datos!$G$2:$G$94,"Sistema",Datos!$F$2:$F$94,1)-SUMIFS(Datos!$Q$2:$Q$94,Datos!$G$2:$G$94,"Sistema",Datos!$F$2:$F$94,1) -> -2000 | E19: Se retiraron los ajustes manuales de Dic-26 (+2.000) y Ene-27 (+1.000) y el -1.000 de Abr-27
B20: Δ Total Demand Assumption | D20: =SUMIFS(Datos!$K$2:$K$94,Datos!$G$2:$G$94,"Sistema",Datos!$F$2:$F$94,1)-SUMIFS(Datos!$R$2:$R$94,Datos!$G$2:$G$94,"Sistema",Datos!$F$2:$F$94,1) -> 1211 | E20: Se limpio el -173/mes que arrastraba TINT BRUSH PINCEAU 03
B21: Δ Otras capas no incluidas en la extraccion (residual) | D21: =(SUMIFS(Datos!$H$2:$H$94,Datos!$G$2:$G$94,"Sistema",Datos!$F$2:$F$94,1)-SUMIFS(Datos!$I$2:$I$94,Datos!$G$2:$G$94,"Sistema",Datos!$F$2:$F$94,1)-SUMIFS(Datos!$J$2:$J$94,Datos!$G$2:$G$94,"Sistema",Datos!$F$2:$F$94,1)-SUMIFS(Datos!$K$2:$K$94,Datos!$G$2:$G$94,"Sistema",Datos!$F$2:$F$94,1))-(SUMIFS(Datos!$O$2:$O$94,Datos!$G$2:$G$94,"Sistema",Datos!$F$2:$F$94,1)-SUMIFS(Datos!$P$2:$P$94,Datos!$G$2:$G$94,"Sistema",Datos!$F$2:$F$94,1)-SUMIFS(Datos!$Q$2:$Q$94,Datos!$G$2:$G$94,"Sistema",Datos!$F$2:$F$94,1)-SUMIFS(Datos!$R$2:$R$94,Datos!$G$2:$G$94,"Sistema",Datos!$F$2:$F$94,1)) -> 884 | E21: Consensus menos la suma de capas extraidas. Initiative / Prometheus no vienen en este extract
B22: Δ Lineas en modo manual (Ignore System FC = 2) | D22: =SUMIFS(Datos!$H$2:$H$94,Datos!$G$2:$G$94,"Manual",Datos!$F$2:$F$94,1)-SUMIFS(Datos!$O$2:$O$94,Datos!$G$2:$G$94,"Manual",Datos!$F$2:$F$94,1) -> -5 | E22: Face Multi: el consensus no se movio, aunque el System FC si (ver hoja Alertas)
B23: W35 - Consensus este ciclo | D23: =SUMIFS(Datos!$H$2:$H$94,Datos!$F$2:$F$94,1) -> 38682 | E23: Punto de llegada
B24: Control (debe dar 0) | D24: =D23-(D17+D18+D19+D20+D21+D22) -> 0
B27: EL NETO ESCONDE EL MOVIMIENTO REAL
B28: Medida | C28: Unidades | D28: Lectura
B29: Cambio NETO del horizonte | D29: =E6-D6 -> -2039 | E29: Lo que ve supply en el total
B30: Movimiento BRUTO (suma de |Δ| por mes) | D30: =SUMPRODUCT(ABS('Por Mes'!F6:F13)) -> 7429 | E30: Volumen que efectivamente se re-faseo entre meses
B31: Movimiento BRUTO (suma de |Δ| por EAN x mes) | D31: =SUMPRODUCT(ABS('EAN x Mes'!C6:J13)) -> 9163 | E31: Volumen re-faseado a nivel codigo x mes
B32: Ratio bruto / neto (por mes) | D32: =IFERROR(D30/ABS(D29),"") -> 3.6434527 | E32: Por cada unidad de cambio neto se movieron ~3,6 unidades de fase
B35: MENSAJES PARA LA PRESENTACION
B36: Bloque | C36: Mensaje
B37: Vs LC | D37: El scope de brochas y accesorios de Kylie cierra el ciclo en -2,0K u / -5% sobre M09-M04. El numero total casi no se movio: lo que cambio fue la fase.
B38: Vs LC | D38: El 100% del descenso neto viene de UN codigo: TINT BRUSH PINCEAU 03 (-2,5K u / -10%). El resto del scope suma +0,5K u.
B39: Vs LC | D39: Se adelanto volumen a Sep-26 (+1,6K / +25%) y se saco de Oct-26 (-1,3K / -24%), Mar-27 (-1,9K / -28%) y Abr-27 (-1,2K / -32%). Q1 sube, Q3 y Q4 bajan.
B40: Vs LC | D40: El movimiento es de sistema, no de criterio: el System FC bajo -2,1K u y ademas se retiraron todos los ajustes manuales (RA -2,0K, TDA +1,2K al limpiar el -173/mes).
B41: Vs LY | D41: El -31,5% vs LY es un artefacto: Feb-26 cargo 23,6K u de pipe-fill de dos brochas nuevas (KJCLIP 9,6K + UNVL BLSH 7,3K). Neutralizando Feb, el scope esta en +2,2% vs LY.
B42: Vs LY | D42: Face Multi -50% vs LY es el mismo efecto base. Accesories -22% vs LY es real y se explica por TINT BRUSH PINCEAU 03 (-6,1K u vs LY).
B43: Riesgo | D43: UNVL BLSH PINCEAU04: el System FC subio a 11,1K u y el consensus se quedo en 6,5K por Total Demand Assumption. Gap de +4,6K u sin revisar.
B44: Riesgo | D44: PRS SCLP CMPLN 05: el System FC se fue a 0 y el consensus termina en Mar-27. Confirmar si es descontinuacion o hueco de mantenimiento.

Sheet Por Mes
A1: Consensus - Final por mes
A2: Horizonte de foco sombreado. Unidades.
A4: Mes | B4: Trim. FY | C4: LY | D4: W34 | E4: W35 | F4: Δ vs LC (u) | G4: Δ vs LC (%) | H4: Δ vs LY (u) | I4: Δ vs LY (%) | J4: W35 System FC | K4: W34 System FC | L4: Δ System FC
A5: Cerrado / en curso
A6: 2026.M09 | B6: FY27 Q1 | C6: =SUMIFS(Datos!$T$2:$T$94,Datos!$D$2:$D$94,"2026.M09") -> 5552 | D6: =SUMIFS(Datos!$O$2:$O$94,Datos!$D$2:$D$94,"2026.M09") -> 6409 | E6: =SUMIFS(Datos!$H$2:$H$94,Datos!$D$2:$D$94,"2026.M09") -> 7992 | F6: =E6-D6 -> 1583 | G6: =IFERROR(E6/D6-1,"") -> 0.24699641 | H6: =E6-C6 -> 2440 | I6: =IFERROR(E6/C6-1,"") -> 0.43948127 | J6: =SUMIFS(Datos!$I$2:$I$94,Datos!$D$2:$D$94,"2026.M09") -> 6922 | K6: =SUMIFS(Datos!$P$2:$P$94,Datos!$D$2:$D$94,"2026.M09") -> 5461 | L6: =J6-K6 -> 1461
A7: 2026.M10 | B7: FY27 Q2 | C7: =SUMIFS(Datos!$T$2:$T$94,Datos!$D$2:$D$94,"2026.M10") -> 5835 | D7: =SUMIFS(Datos!$O$2:$O$94,Datos!$D$2:$D$94,"2026.M10") -> 5404 | E7: =SUMIFS(Datos!$H$2:$H$94,Datos!$D$2:$D$94,"2026.M10") -> 4103 | F7: =E7-D7 -> -1301 | G7: =IFERROR(E7/D7-1,"") -> -0.24074759 | H7: =E7-C7 -> -1732 | I7: =IFERROR(E7/C7-1,"") -> -0.29682948 | J7: =SUMIFS(Datos!$I$2:$I$94,Datos!$D$2:$D$94,"2026.M10") -> 3693 | K7: =SUMIFS(Datos!$P$2:$P$94,Datos!$D$2:$D$94,"2026.M10") -> 5666 | L7: =J7-K7 -> -1973
A8: 2026.M11 | B8: FY27 Q2 | C8: =SUMIFS(Datos!$T$2:$T$94,Datos!$D$2:$D$94,"2026.M11") -> 3197 | D8: =SUMIFS(Datos!$O$2:$O$94,Datos!$D$2:$D$94,"2026.M11") -> 4300 | E8: =SUMIFS(Datos!$H$2:$H$94,Datos!$D$2:$D$94,"2026.M11") -> 4692 | F8: =E8-D8 -> 392 | G8: =IFERROR(E8/D8-1,"") -> 0.091162791 | H8: =E8-C8 -> 1495 | I8: =IFERROR(E8/C8-1,"") -> 0.4676259 | J8: =SUMIFS(Datos!$I$2:$I$94,Datos!$D$2:$D$94,"2026.M11") -> 4602 | K8: =SUMIFS(Datos!$P$2:$P$94,Datos!$D$2:$D$94,"2026.M11") -> 4705 | L8: =J8-K8 -> -103
A9: 2026.M12 | B9: FY27 Q2 | C9: =SUMIFS(Datos!$T$2:$T$94,Datos!$D$2:$D$94,"2026.M12") -> 3799 | D9: =SUMIFS(Datos!$O$2:$O$94,Datos!$D$2:$D$94,"2026.M12") -> 4587 | E9: =SUMIFS(Datos!$H$2:$H$94,Datos!$D$2:$D$94,"2026.M12") -> 5187 | F9: =E9-D9 -> 600 | G9: =IFERROR(E9/D9-1,"") -> 0.13080445 | H9: =E9-C9 -> 1388 | I9: =IFERROR(E9/C9-1,"") -> 0.36535931 | J9: =SUMIFS(Datos!$I$2:$I$94,Datos!$D$2:$D$94,"2026.M12") -> 5455 | K9: =SUMIFS(Datos!$P$2:$P$94,Datos!$D$2:$D$94,"2026.M12") -> 3102 | L9: =J9-K9 -> 2353
A10: 2027.M01 | B10: FY27 Q3 | C10: =SUMIFS(Datos!$T$2:$T$94,Datos!$D$2:$D$94,"2027.M01") -> 4289 | D10: =SUMIFS(Datos!$O$2:$O$94,Datos!$D$2:$D$94,"2027.M01") -> 4023 | E10: =SUMIFS(Datos!$H$2:$H$94,Datos!$D$2:$D$94,"2027.M01") -> 4143 | F10: =E10-D10 -> 120 | G10: =IFERROR(E10/D10-1,"") -> 0.029828486 | H10: =E10-C10 -> -146 | I10: =IFERROR(E10/C10-1,"") -> -0.034040569 | J10: =SUMIFS(Datos!$I$2:$I$94,Datos!$D$2:$D$94,"2027.M01") -> 5426 | K10: =SUMIFS(Datos!$P$2:$P$94,Datos!$D$2:$D$94,"2027.M01") -> 3819 | L10: =J10-K10 -> 1607
A11: 2027.M02 | B11: FY27 Q3 | C11: =SUMIFS(Datos!$T$2:$T$94,Datos!$D$2:$D$94,"2027.M02") -> 23589 | D11: =SUMIFS(Datos!$O$2:$O$94,Datos!$D$2:$D$94,"2027.M02") -> 5430 | E11: =SUMIFS(Datos!$H$2:$H$94,Datos!$D$2:$D$94,"2027.M02") -> 5114 | F11: =E11-D11 -> -316 | G11: =IFERROR(E11/D11-1,"") -> -0.058195212 | H11: =E11-C11 -> -18475 | I11: =IFERROR(E11/C11-1,"") -> -0.78320404 | J11: =SUMIFS(Datos!$I$2:$I$94,Datos!$D$2:$D$94,"2027.M02") -> 5628 | K11: =SUMIFS(Datos!$P$2:$P$94,Datos!$D$2:$D$94,"2027.M02") -> 6157 | L11: =J11-K11 -> -529
A12: 2027.M03 | B12: FY27 Q3 | C12: =SUMIFS(Datos!$T$2:$T$94,Datos!$D$2:$D$94,"2027.M03") -> 6879 | D12: =SUMIFS(Datos!$O$2:$O$94,Datos!$D$2:$D$94,"2027.M03") -> 6731 | E12: =SUMIFS(Datos!$H$2:$H$94,Datos!$D$2:$D$94,"2027.M03") -> 4844 | F12: =E12-D12 -> -1887 | G12: =IFERROR(E12/D12-1,"") -> -0.28034467 | H12: =E12-C12 -> -2035 | I12: =IFERROR(E12/C12-1,"") -> -0.29582788 | J12: =SUMIFS(Datos!$I$2:$I$94,Datos!$D$2:$D$94,"2027.M03") -> 5261 | K12: =SUMIFS(Datos!$P$2:$P$94,Datos!$D$2:$D$94,"2027.M03") -> 7689 | L12: =J12-K12 -> -2428
A13: 2027.M04 | B13: FY27 Q4 | C13: =SUMIFS(Datos!$T$2:$T$94,Datos!$D$2:$D$94,"2027.M04") -> 3298 | D13: =SUMIFS(Datos!$O$2:$O$94,Datos!$D$2:$D$94,"2027.M04") -> 3837 | E13: =SUMIFS(Datos!$H$2:$H$94,Datos!$D$2:$D$94,"2027.M04") -> 2607 | F13: =E13-D13 -> -1230 | G13: =IFERROR(E13/D13-1,"") -> -0.32056294 | H13: =E13-C13 -> -691 | I13: =IFERROR(E13/C13-1,"") -> -0.20952092 | J13: =SUMIFS(Datos!$I$2:$I$94,Datos!$D$2:$D$94,"2027.M04") -> 2711 | K13: =SUMIFS(Datos!$P$2:$P$94,Datos!$D$2:$D$94,"2027.M04") -> 5810 | L13: =J13-K13 -> -3099
A14: TOTAL M09-M04 | C14: =SUM(C6:C13) -> 56438 | D14: =SUM(D6:D13) -> 40721 | E14: =SUM(E6:E13) -> 38682 | F14: =E14-D14 -> -2039 | G14: =IFERROR(E14/D14-1,"") -> -0.050072444 | H14: =E14-C14 -> -17756 | I14: =IFERROR(E14/C14-1,"") -> -0.31461072 | J14: =SUM(J6:J13) -> 39698 | K14: =SUM(K6:K13) -> 42409 | L14: =SUM(L6:L13) -> -2711
A16: Fuera del horizonte de foco (contexto)
A17: Mes | B17: Trim. FY | C17: LY | D17: W34 | E17: W35 | F17: Δ vs LC (u) | G17: Δ vs LC (%) | H17: Δ vs LY (u) | I17: Δ vs LY (%) | J17: W35 System FC | K17: W34 System FC | L17: Δ System FC
A18: 2026.M07 | B18: FY26 Q4 | C18: =SUMIFS(Datos!$T$2:$T$94,Datos!$D$2:$D$94,"2026.M07") -> 5747 | D18: =SUMIFS(Datos!$O$2:$O$94,Datos!$D$2:$D$94,"2026.M07") -> 8747 | E18: =SUMIFS(Datos!$H$2:$H$94,Datos!$D$2:$D$94,"2026.M07") -> 8747 | F18: =E18-D18 -> 0 | G18: =IFERROR(E18/D18-1,"") -> 0 | H18: =E18-C18 -> 3000 | I18: =IFERROR(E18/C18-1,"") -> 0.52201148 | J18: =SUMIFS(Datos!$I$2:$I$94,Datos!$D$2:$D$94,"2026.M07") -> 8747 | K18: =SUMIFS(Datos!$P$2:$P$94,Datos!$D$2:$D$94,"2026.M07") -> 8747 | L18: =J18-K18 -> 0
A19: 2026.M08 | B19: FY27 Q1 | C19: =SUMIFS(Datos!$T$2:$T$94,Datos!$D$2:$D$94,"2026.M08") -> 2528 | D19: =SUMIFS(Datos!$O$2:$O$94,Datos!$D$2:$D$94,"2026.M08") -> 9871.3333 | E19: =SUMIFS(Datos!$H$2:$H$94,Datos!$D$2:$D$94,"2026.M08") -> 7293 | F19: =E19-D19 -> -2578.3333 | G19: =IFERROR(E19/D19-1,"") -> -0.26119403 | H19: =E19-C19 -> 4765 | I19: =IFERROR(E19/C19-1,"") -> 1.8848892 | J19: =SUMIFS(Datos!$I$2:$I$94,Datos!$D$2:$D$94,"2026.M08") -> 7293 | K19: =SUMIFS(Datos!$P$2:$P$94,Datos!$D$2:$D$94,"2026.M08") -> 8321 | L19: =J19-K19 -> -1028
A20: 2027.M05 | B20: FY27 Q4 | C20: =SUMIFS(Datos!$T$2:$T$94,Datos!$D$2:$D$94,"2027.M05") -> 5335 | D20: =SUMIFS(Datos!$O$2:$O$94,Datos!$D$2:$D$94,"2027.M05") -> 5309 | E20: =SUMIFS(Datos!$H$2:$H$94,Datos!$D$2:$D$94,"2027.M05") -> 4362 | F20: =E20-D20 -> -947 | G20: =IFERROR(E20/D20-1,"") -> -0.17837634 | H20: =E20-C20 -> -973 | I20: =IFERROR(E20/C20-1,"") -> -0.18238051 | J20: =SUMIFS(Datos!$I$2:$I$94,Datos!$D$2:$D$94,"2027.M05") -> 4757 | K20: =SUMIFS(Datos!$P$2:$P$94,Datos!$D$2:$D$94,"2027.M05") -> 6007 | L20: =J20-K20 -> -1250
A21: 2027.M06 | B21: FY27 Q4 | C21: =SUMIFS(Datos!$T$2:$T$94,Datos!$D$2:$D$94,"2027.M06") -> 4019 | D21: =SUMIFS(Datos!$O$2:$O$94,Datos!$D$2:$D$94,"2027.M06") -> 5673 | E21: =SUMIFS(Datos!$H$2:$H$94,Datos!$D$2:$D$94,"2027.M06") -> 5435 | F21: =E21-D21 -> -238 | G21: =IFERROR(E21/D21-1,"") -> -0.041953111 | H21: =E21-C21 -> 1416 | I21: =IFERROR(E21/C21-1,"") -> 0.35232645 | J21: =SUMIFS(Datos!$I$2:$I$94,Datos!$D$2:$D$94,"2027.M06") -> 6389 | K21: =SUMIFS(Datos!$P$2:$P$94,Datos!$D$2:$D$94,"2027.M06") -> 6072 | L21: =J21-K21 -> 317
A23: 2026.M07 esta cerrado (System FC = Consensus = Actuals) y 2026.M08 sigue facturando: por eso quedan fuera del foco.

Sheet Product Lines
A1: Top Product Lines - W35 vs W34 vs LY
A2: Horizonte 2026.M09 - 2027.M04. Unidades.
A4: Product Line | B4: # EAN | C4: LY | D4: W34 | E4: W35 | F4: % del libro W35 | G4: Δ vs LC (u) | H4: Δ vs LC (%) | I4: Δ vs LY (u) | J4: Δ vs LY (%) | K4: Δ vs LY ex-Feb27 (u) | L4: Contribucion al Δ LC
A5: Accesories (00006010) | B5: 4 | C5: =SUMIFS(Datos!$T$2:$T$94,Datos!$A$2:$A$94,"Accesories (00006010)",Datos!$F$2:$F$94,1) -> 37826 | D5: =SUMIFS(Datos!$O$2:$O$94,Datos!$A$2:$A$94,"Accesories (00006010)",Datos!$F$2:$F$94,1) -> 31528 | E5: =SUMIFS(Datos!$H$2:$H$94,Datos!$A$2:$A$94,"Accesories (00006010)",Datos!$F$2:$F$94,1) -> 29494 | F5: =IFERROR(E5/E$99,"") -> 0.7624735 | G5: =E5-D5 -> -2034 | H5: =IFERROR(E5/D5-1,"") -> -0.064514083 | I5: =E5-C5 -> -8332 | J5: =IFERROR(E5/C5-1,"") -> -0.22027177 | K5: =SUMIFS(Datos!$H$2:$H$94,Datos!$A$2:$A$94,"Accesories (00006010)",Datos!$D$2:$D$94,"<>2027.M02",Datos!$F$2:$F$94,1)-SUMIFS(Datos!$T$2:$T$94,Datos!$A$2:$A$94,"Accesories (00006010)",Datos!$D$2:$D$94,"<>2027.M02",Datos!$F$2:$F$94,1) -> -5856 | L5: =IFERROR(G5/$G$99,"") -> 0.99754782
A6: Face Multi (00006011) | B6: 3 | C6: =SUMIFS(Datos!$T$2:$T$94,Datos!$A$2:$A$94,"Face Multi (00006011)",Datos!$F$2:$F$94,1) -> 18473 | D6: =SUMIFS(Datos!$O$2:$O$94,Datos!$A$2:$A$94,"Face Multi (00006011)",Datos!$F$2:$F$94,1) -> 9193 | E6: =SUMIFS(Datos!$H$2:$H$94,Datos!$A$2:$A$94,"Face Multi (00006011)",Datos!$F$2:$F$94,1) -> 9188 | F6: =IFERROR(E6/E$99,"") -> 0.2375265 | G6: =E6-D6 -> -5 | H6: =IFERROR(E6/D6-1,"") -> -0.00054389209 | I6: =E6-C6 -> -9285 | J6: =IFERROR(E6/C6-1,"") -> -0.50262545 | K6: =SUMIFS(Datos!$H$2:$H$94,Datos!$A$2:$A$94,"Face Multi (00006011)",Datos!$D$2:$D$94,"<>2027.M02",Datos!$F$2:$F$94,1)-SUMIFS(Datos!$T$2:$T$94,Datos!$A$2:$A$94,"Face Multi (00006011)",Datos!$D$2:$D$94,"<>2027.M02",Datos!$F$2:$F$94,1) -> 6693 | L6: =IFERROR(G6/$G$99,"") -> 0.0024521824
A7: Kylie Eye Brushes (00006121) | B7: 1 | C7: =SUMIFS(Datos!$T$2:$T$94,Datos!$A$2:$A$94,"Kylie Eye Brushes (00006121)",Datos!$F$2:$F$94,1) -> 139 | D7: =SUMIFS(Datos!$O$2:$O$94,Datos!$A$2:$A$94,"Kylie Eye Brushes (00006121)",Datos!$F$2:$F$94,1) -> 0 | E7: =SUMIFS(Datos!$H$2:$H$94,Datos!$A$2:$A$94,"Kylie Eye Brushes (00006121)",Datos!$F$2:$F$94,1) -> 0 | F7: =IFERROR(E7/E$99,"") -> 0 | G7: =E7-D7 -> 0 | H7: =IFERROR(E7/D7-1,"") | I7: =E7-C7 -> -139 | J7: =IFERROR(E7/C7-1,"") -> -1 | K7: =SUMIFS(Datos!$H$2:$H$94,Datos!$A$2:$A$94,"Kylie Eye Brushes (00006121)",Datos!$D$2:$D$94,"<>2027.M02",Datos!$F$2:$F$94,1)-SUMIFS(Datos!$T$2:$T$94,Datos!$A$2:$A$94,"Kylie Eye Brushes (00006121)",Datos!$D$2:$D$94,"<>2027.M02",Datos!$F$2:$F$94,1) -> -118 | L7: =IFERROR(G7/$G$99,"") -> 0
A8: TOTAL | B8: =SUM(B5:B7) -> 8 | C8: =SUM(C5:C7) -> 56438 | D8: =SUM(D5:D7) -> 40721 | E8: =SUM(E5:E7) -> 38682 | F8: =IFERROR(E8/E$99,"") -> 1 | G8: =SUM(G5:G7) -> -2039 | H8: =IFERROR(E8/D8-1,"") -> -0.050072444 | I8: =SUM(I5:I7) -> -17756 | J8: =IFERROR(E8/C8-1,"") -> -0.31461072 | K8: =SUM(K5:K7) -> 719 | L8: =IFERROR(G8/$G$99,"") -> 1
A10: Detalle mensual por Product Line - Δ vs LC (u)
A11: Product Line | B11: 2026.M09 | C11: 2026.M10 | D11: 2026.M11 | E11: 2026.M12 | F11: 2027.M01 | G11: 2027.M02 | H11: 2027.M03 | I11: 2027.M04 | J11: Total
A12: Accesories (00006010) | B12: =SUMIFS(Datos!$H$2:$H$94,Datos!$A$2:$A$94,"Accesories (00006010)",Datos!$D$2:$D$94,"2026.M09")-SUMIFS(Datos!$O$2:$O$94,Datos!$A$2:$A$94,"Accesories (00006010)",Datos!$D$2:$D$94,"2026.M09") -> 1588 | C12: =SUMIFS(Datos!$H$2:$H$94,Datos!$A$2:$A$94,"Accesories (00006010)",Datos!$D$2:$D$94,"2026.M10")-SUMIFS(Datos!$O$2:$O$94,Datos!$A$2:$A$94,"Accesories (00006010)",Datos!$D$2:$D$94,"2026.M10") -> -1301 | D12: =SUMIFS(Datos!$H$2:$H$94,Datos!$A$2:$A$94,"Accesories (00006010)",Datos!$D$2:$D$94,"2026.M11")-SUMIFS(Datos!$O$2:$O$94,Datos!$A$2:$A$94,"Accesories (00006010)",Datos!$D$2:$D$94,"2026.M11") -> 392 | E12: =SUMIFS(Datos!$H$2:$H$94,Datos!$A$2:$A$94,"Accesories (00006010)",Datos!$D$2:$D$94,"2026.M12")-SUMIFS(Datos!$O$2:$O$94,Datos!$A$2:$A$94,"Accesories (00006010)",Datos!$D$2:$D$94,"2026.M12") -> 600 | F12: =SUMIFS(Datos!$H$2:$H$94,Datos!$A$2:$A$94,"Accesories (00006010)",Datos!$D$2:$D$94,"2027.M01")-SUMIFS(Datos!$O$2:$O$94,Datos!$A$2:$A$94,"Accesories (00006010)",Datos!$D$2:$D$94,"2027.M01") -> 120 | G12: =SUMIFS(Datos!$H$2:$H$94,Datos!$A$2:$A$94,"Accesories (00006010)",Datos!$D$2:$D$94,"2027.M02")-SUMIFS(Datos!$O$2:$O$94,Datos!$A$2:$A$94,"Accesories (00006010)",Datos!$D$2:$D$94,"2027.M02") -> -316 | H12: =SUMIFS(Datos!$H$2:$H$94,Datos!$A$2:$A$94,"Accesories (00006010)",Datos!$D$2:$D$94,"2027.M03")-SUMIFS(Datos!$O$2:$O$94,Datos!$A$2:$A$94,"Accesories (00006010)",Datos!$D$2:$D$94,"2027.M03") -> -1887 | I12: =SUMIFS(Datos!$H$2:$H$94,Datos!$A$2:$A$94,"Accesories (00006010)",Datos!$D$2:$D$94,"2027.M04")-SUMIFS(Datos!$O$2:$O$94,Datos!$A$2:$A$94,"Accesories (00006010)",Datos!$D$2:$D$94,"2027.M04") -> -1230 | J12: =SUM(B12:I12) -> -2034
A13: Face Multi (00006011) | B13: =SUMIFS(Datos!$H$2:$H$94,Datos!$A$2:$A$94,"Face Multi (00006011)",Datos!$D$2:$D$94,"2026.M09")-SUMIFS(Datos!$O$2:$O$94,Datos!$A$2:$A$94,"Face Multi (00006011)",Datos!$D$2:$D$94,"2026.M09") -> -5 | C13: =SUMIFS(Datos!$H$2:$H$94,Datos!$A$2:$A$94,"Face Multi (00006011)",Datos!$D$2:$D$94,"2026.M10")-SUMIFS(Datos!$O$2:$O$94,Datos!$A$2:$A$94,"Face Multi (00006011)",Datos!$D$2:$D$94,"2026.M10") -> 0 | D13: =SUMIFS(Datos!$H$2:$H$94,Datos!$A$2:$A$94,"Face Multi (00006011)",Datos!$D$2:$D$94,"2026.M11")-SUMIFS(Datos!$O$2:$O$94,Datos!$A$2:$A$94,"Face Multi (00006011)",Datos!$D$2:$D$94,"2026.M11") -> 0 | E13: =SUMIFS(Datos!$H$2:$H$94,Datos!$A$2:$A$94,"Face Multi (00006011)",Datos!$D$2:$D$94,"2026.M12")-SUMIFS(Datos!$O$2:$O$94,Datos!$A$2:$A$94,"Face Multi (00006011)",Datos!$D$2:$D$94,"2026.M12") -> 0 | F13: =SUMIFS(Datos!$H$2:$H$94,Datos!$A$2:$A$94,"Face Multi (00006011)",Datos!$D$2:$D$94,"2027.M01")-SUMIFS(Datos!$O$2:$O$94,Datos!$A$2:$A$94,"Face Multi (00006011)",Datos!$D$2:$D$94,"2027.M01") -> 0 | G13: =SUMIFS(Datos!$H$2:$H$94,Datos!$A$2:$A$94,"Face Multi (00006011)",Datos!$D$2:$D$94,"2027.M02")-SUMIFS(Datos!$O$2:$O$94,Datos!$A$2:$A$94,"Face Multi (00006011)",Datos!$D$2:$D$94,"2027.M02") -> 0 | H13: =SUMIFS(Datos!$H$2:$H$94,Datos!$A$2:$A$94,"Face Multi (00006011)",Datos!$D$2:$D$94,"2027.M03")-SUMIFS(Datos!$O$2:$O$94,Datos!$A$2:$A$94,"Face Multi (00006011)",Datos!$D$2:$D$94,"2027.M03") -> 0 | I13: =SUMIFS(Datos!$H$2:$H$94,Datos!$A$2:$A$94,"Face Multi (00006011)",Datos!$D$2:$D$94,"2027.M04")-SUMIFS(Datos!$O$2:$O$94,Datos!$A$2:$A$94,"Face Multi (00006011)",Datos!$D$2:$D$94,"2027.M04") -> 0 | J13: =SUM(B13:I13) -> -5
A14: Kylie Eye Brushes (00006121) | B14: =SUMIFS(Datos!$H$2:$H$94,Datos!$A$2:$A$94,"Kylie Eye Brushes (00006121)",Datos!$D$2:$D$94,"2026.M09")-SUMIFS(Datos!$O$2:$O$94,Datos!$A$2:$A$94,"Kylie Eye Brushes (00006121)",Datos!$D$2:$D$94,"2026.M09") -> 0 | C14: =SUMIFS(Datos!$H$2:$H$94,Datos!$A$2:$A$94,"Kylie Eye Brushes (00006121)",Datos!$D$2:$D$94,"2026.M10")-SUMIFS(Datos!$O$2:$O$94,Datos!$A$2:$A$94,"Kylie Eye Brushes (00006121)",Datos!$D$2:$D$94,"2026.M10") -> 0 | D14: =SUMIFS(Datos!$H$2:$H$94,Datos!$A$2:$A$94,"Kylie Eye Brushes (00006121)",Datos!$D$2:$D$94,"2026.M11")-SUMIFS(Datos!$O$2:$O$94,Datos!$A$2:$A$94,"Kylie Eye Brushes (00006121)",Datos!$D$2:$D$94,"2026.M11") -> 0 | E14: =SUMIFS(Datos!$H$2:$H$94,Datos!$A$2:$A$94,"Kylie Eye Brushes (00006121)",Datos!$D$2:$D$94,"2026.M12")-SUMIFS(Datos!$O$2:$O$94,Datos!$A$2:$A$94,"Kylie Eye Brushes (00006121)",Datos!$D$2:$D$94,"2026.M12") -> 0 | F14: =SUMIFS(Datos!$H$2:$H$94,Datos!$A$2:$A$94,"Kylie Eye Brushes (00006121)",Datos!$D$2:$D$94,"2027.M01")-SUMIFS(Datos!$O$2:$O$94,Datos!$A$2:$A$94,"Kylie Eye Brushes (00006121)",Datos!$D$2:$D$94,"2027.M01") -> 0 | G14: =SUMIFS(Datos!$H$2:$H$94,Datos!$A$2:$A$94,"Kylie Eye Brushes (00006121)",Datos!$D$2:$D$94,"2027.M02")-SUMIFS(Datos!$O$2:$O$94,Datos!$A$2:$A$94,"Kylie Eye Brushes (00006121)",Datos!$D$2:$D$94,"2027.M02") -> 0 | H14: =SUMIFS(Datos!$H$2:$H$94,Datos!$A$2:$A$94,"Kylie Eye Brushes (00006121)",Datos!$D$2:$D$94,"2027.M03")-SUMIFS(Datos!$O$2:$O$94,Datos!$A$2:$A$94,"Kylie Eye Brushes (00006121)",Datos!$D$2:$D$94,"2027.M03") -> 0 | I14: =SUMIFS(Datos!$H$2:$H$94,Datos!$A$2:$A$94,"Kylie Eye Brushes (00006121)",Datos!$D$2:$D$94,"2027.M04")-SUMIFS(Datos!$O$2:$O$94,Datos!$A$2:$A$94,"Kylie Eye Brushes (00006121)",Datos!$D$2:$D$94,"2027.M04") -> 0 | J14: =SUM(B14:I14) -> 0
A15: TOTAL | B15: =SUM(B12:B14) -> 1583 | C15: =SUM(C12:C14) -> -1301 | D15: =SUM(D12:D14) -> 392 | E15: =SUM(E12:E14) -> 600 | F15: =SUM(F12:F14) -> 120 | G15: =SUM(G12:G14) -> -316 | H15: =SUM(H12:H14) -> -1887 | I15: =SUM(I12:I14) -> -1230 | J15: =SUM(J12:J14) -> -2039
A17: Detalle mensual por Product Line - Consensus W35 (u)
A18: Product Line | B18: 2026.M09 | C18: 2026.M10 | D18: 2026.M11 | E18: 2026.M12 | F18: 2027.M01 | G18: 2027.M02 | H18: 2027.M03 | I18: 2027.M04 | J18: Total
A19: Accesories (00006010) | B19: =SUMIFS(Datos!$H$2:$H$94,Datos!$A$2:$A$94,"Accesories (00006010)",Datos!$D$2:$D$94,"2026.M09") -> 5592 | C19: =SUMIFS(Datos!$H$2:$H$94,Datos!$A$2:$A$94,"Accesories (00006010)",Datos!$D$2:$D$94,"2026.M10") -> 2707 | D19: =SUMIFS(Datos!$H$2:$H$94,Datos!$A$2:$A$94,"Accesories (00006010)",Datos!$D$2:$D$94,"2026.M11") -> 3464 | E19: =SUMIFS(Datos!$H$2:$H$94,Datos!$A$2:$A$94,"Accesories (00006010)",Datos!$D$2:$D$94,"2026.M12") -> 4083 | F19: =SUMIFS(Datos!$H$2:$H$94,Datos!$A$2:$A$94,"Accesories (00006010)",Datos!$D$2:$D$94,"2027.M01") -> 3282 | G19: =SUMIFS(Datos!$H$2:$H$94,Datos!$A$2:$A$94,"Accesories (00006010)",Datos!$D$2:$D$94,"2027.M02") -> 4264 | H19: =SUMIFS(Datos!$H$2:$H$94,Datos!$A$2:$A$94,"Accesories (00006010)",Datos!$D$2:$D$94,"2027.M03") -> 4145 | I19: =SUMIFS(Datos!$H$2:$H$94,Datos!$A$2:$A$94,"Accesories (00006010)",Datos!$D$2:$D$94,"2027.M04") -> 1957 | J19: =SUM(B19:I19) -> 29494
A20: Face Multi (00006011) | B20: =SUMIFS(Datos!$H$2:$H$94,Datos!$A$2:$A$94,"Face Multi (00006011)",Datos!$D$2:$D$94,"2026.M09") -> 2400 | C20: =SUMIFS(Datos!$H$2:$H$94,Datos!$A$2:$A$94,"Face Multi (00006011)",Datos!$D$2:$D$94,"2026.M10") -> 1396 | D20: =SUMIFS(Datos!$H$2:$H$94,Datos!$A$2:$A$94,"Face Multi (00006011)",Datos!$D$2:$D$94,"2026.M11") -> 1228 | E20: =SUMIFS(Datos!$H$2:$H$94,Datos!$A$2:$A$94,"Face Multi (00006011)",Datos!$D$2:$D$94,"2026.M12") -> 1104 | F20: =SUMIFS(Datos!$H$2:$H$94,Datos!$A$2:$A$94,"Face Multi (00006011)",Datos!$D$2:$D$94,"2027.M01") -> 861 | G20: =SUMIFS(Datos!$H$2:$H$94,Datos!$A$2:$A$94,"Face Multi (00006011)",Datos!$D$2:$D$94,"2027.M02") -> 850 | H20: =SUMIFS(Datos!$H$2:$H$94,Datos!$A$2:$A$94,"Face Multi (00006011)",Datos!$D$2:$D$94,"2027.M03") -> 699 | I20: =SUMIFS(Datos!$H$2:$H$94,Datos!$A$2:$A$94,"Face Multi (00006011)",Datos!$D$2:$D$94,"2027.M04") -> 650 | J20: =SUM(B20:I20) -> 9188
A21: Kylie Eye Brushes (00006121) | B21: =SUMIFS(Datos!$H$2:$H$94,Datos!$A$2:$A$94,"Kylie Eye Brushes (00006121)",Datos!$D$2:$D$94,"2026.M09") -> 0 | C21: =SUMIFS(Datos!$H$2:$H$94,Datos!$A$2:$A$94,"Kylie Eye Brushes (00006121)",Datos!$D$2:$D$94,"2026.M10") -> 0 | D21: =SUMIFS(Datos!$H$2:$H$94,Datos!$A$2:$A$94,"Kylie Eye Brushes (00006121)",Datos!$D$2:$D$94,"2026.M11") -> 0 | E21: =SUMIFS(Datos!$H$2:$H$94,Datos!$A$2:$A$94,"Kylie Eye Brushes (00006121)",Datos!$D$2:$D$94,"2026.M12") -> 0 | F21: =SUMIFS(Datos!$H$2:$H$94,Datos!$A$2:$A$94,"Kylie Eye Brushes (00006121)",Datos!$D$2:$D$94,"2027.M01") -> 0 | G21: =SUMIFS(Datos!$H$2:$H$94,Datos!$A$2:$A$94,"Kylie Eye Brushes (00006121)",Datos!$D$2:$D$94,"2027.M02") -> 0 | H21: =SUMIFS(Datos!$H$2:$H$94,Datos!$A$2:$A$94,"Kylie Eye Brushes (00006121)",Datos!$D$2:$D$94,"2027.M03") -> 0 | I21: =SUMIFS(Datos!$H$2:$H$94,Datos!$A$2:$A$94,"Kylie Eye Brushes (00006121)",Datos!$D$2:$D$94,"2027.M04") -> 0 | J21: =SUM(B21:I21) -> 0
A22: TOTAL | B22: =SUM(B19:B21) -> 7992 | C22: =SUM(C19:C21) -> 4103 | D22: =SUM(D19:D21) -> 4692 | E22: =SUM(E19:E21) -> 5187 | F22: =SUM(F19:F21) -> 4143 | G22: =SUM(G19:G21) -> 5114 | H22: =SUM(H19:H21) -> 4844 | I22: =SUM(I19:I21) -> 2607 | J22: =SUM(J19:J21) -> 38682
A99: Anclas de calculo (no borrar) | E99: =SUMIFS(Datos!$H$2:$H$94,Datos!$F$2:$F$94,1) -> 38682 | G99: =SUMIFS(Datos!$H$2:$H$94,Datos!$F$2:$F$94,1)-SUMIFS(Datos!$O$2:$O$94,Datos!$F$2:$F$94,1) -> -2039

Sheet Detalle EAN
A1: Detalle por EAN - ordenado por magnitud del cambio vs ciclo pasado
A2: Horizonte 2026.M09 - 2027.M04. Unidades. "Otras capas" = Consensus menos (System FC + Reasonability Adj + Total Demand Assumption).
A4: Product Line | B4: EAN | C4: Planning Item Description | D4: Modo | E4: LY | F4: W34 | G4: W35 | H4: Δ vs LC (u) | I4: Δ vs LC (%) | J4: Δ vs LY (u) | K4: Δ vs LY (%) | L4: Δ System FC | M4: Δ Reason. Adj | N4: Δ Total Dem. Assum. | O4: Δ Otras capas | P4: W35 System FC | Q4: Gap SysFC vs Consensus
A5: Accesories (00006010) | B5: 4064941161349 | C5: KJ MU OTH ACC TINT BRUSH PINCEAU 03 IV | D5: Sistema | E5: =SUMIFS(Datos!$T$2:$T$94,Datos!$B$2:$B$94,"4064941161349",Datos!$F$2:$F$94,1) -> 27544 | F5: =SUMIFS(Datos!$O$2:$O$94,Datos!$B$2:$B$94,"4064941161349",Datos!$F$2:$F$94,1) -> 23922 | G5: =SUMIFS(Datos!$H$2:$H$94,Datos!$B$2:$B$94,"4064941161349",Datos!$F$2:$F$94,1) -> 21414 | H5: =G5-F5 -> -2508 | I5: =IFERROR(G5/F5-1,"") -> -0.10484073 | J5: =G5-E5 -> -6130 | K5: =IFERROR(G5/E5-1,"") -> -0.22255301 | L5: =SUMIFS(Datos!$I$2:$I$94,Datos!$B$2:$B$94,"4064941161349",Datos!$F$2:$F$94,1)-SUMIFS(Datos!$P$2:$P$94,Datos!$B$2:$B$94,"4064941161349",Datos!$F$2:$F$94,1) -> -2504 | M5: =SUMIFS(Datos!$J$2:$J$94,Datos!$B$2:$B$94,"4064941161349",Datos!$F$2:$F$94,1)-SUMIFS(Datos!$Q$2:$Q$94,Datos!$B$2:$B$94,"4064941161349",Datos!$F$2:$F$94,1) -> -2000 | N5: =SUMIFS(Datos!$K$2:$K$94,Datos!$B$2:$B$94,"4064941161349",Datos!$F$2:$F$94,1)-SUMIFS(Datos!$R$2:$R$94,Datos!$B$2:$B$94,"4064941161349",Datos!$F$2:$F$94,1) -> 1211 | O5: =H5-L5-M5-N5 -> 785 | P5: =SUMIFS(Datos!$I$2:$I$94,Datos!$B$2:$B$94,"4064941161349",Datos!$F$2:$F$94,1) -> 20583 | Q5: =P5-G5 -> -831
A6: Accesories (00006010) | B6: 4064941117254 | C6: KJ MU OTH ACC BRUSH CONCE BRUSH IV | D6: Sistema | E6: =SUMIFS(Datos!$T$2:$T$94,Datos!$B$2:$B$94,"4064941117254",Datos!$F$2:$F$94,1) -> 7324 | F6: =SUMIFS(Datos!$O$2:$O$94,Datos!$B$2:$B$94,"4064941117254",Datos!$F$2:$F$94,1) -> 5527 | G6: =SUMIFS(Datos!$H$2:$H$94,Datos!$B$2:$B$94,"4064941117254",Datos!$F$2:$F$94,1) -> 5869 | H6: =G6-F6 -> 342 | I6: =IFERROR(G6/F6-1,"") -> 0.061878053 | J6: =G6-E6 -> -1455 | K6: =IFERROR(G6/E6-1,"") -> -0.19866193 | L6: =SUMIFS(Datos!$I$2:$I$94,Datos!$B$2:$B$94,"4064941117254",Datos!$F$2:$F$94,1)-SUMIFS(Datos!$P$2:$P$94,Datos!$B$2:$B$94,"4064941117254",Datos!$F$2:$F$94,1) -> 270 | M6: =SUMIFS(Datos!$J$2:$J$94,Datos!$B$2:$B$94,"4064941117254",Datos!$F$2:$F$94,1)-SUMIFS(Datos!$Q$2:$Q$94,Datos!$B$2:$B$94,"4064941117254",Datos!$F$2:$F$94,1) -> 0 | N6: =SUMIFS(Datos!$K$2:$K$94,Datos!$B$2:$B$94,"4064941117254",Datos!$F$2:$F$94,1)-SUMIFS(Datos!$R$2:$R$94,Datos!$B$2:$B$94,"4064941117254",Datos!$F$2:$F$94,1) -> 0 | O6: =H6-L6-M6-N6 -> 72 | P6: =SUMIFS(Datos!$I$2:$I$94,Datos!$B$2:$B$94,"4064941117254",Datos!$F$2:$F$94,1) -> 5797 | Q6: =P6-G6 -> -72
A7: Accesories (00006010) | B7: 4064941117261 | C7: KJ MU OTH ACC RG BRUSH FOUND 23IV | D7: Sistema | E7: =SUMIFS(Datos!$T$2:$T$94,Datos!$B$2:$B$94,"4064941117261",Datos!$F$2:$F$94,1) -> 1073 | F7: =SUMIFS(Datos!$O$2:$O$94,Datos!$B$2:$B$94,"4064941117261",Datos!$F$2:$F$94,1) -> 1144 | G7: =SUMIFS(Datos!$H$2:$H$94,Datos!$B$2:$B$94,"4064941117261",Datos!$F$2:$F$94,1) -> 1237 | H7: =G7-F7 -> 93 | I7: =IFERROR(G7/F7-1,"") -> 0.081293706 | J7: =G7-E7 -> 164 | K7: =IFERROR(G7/E7-1,"") -> 0.1528425 | L7: =SUMIFS(Datos!$I$2:$I$94,Datos!$B$2:$B$94,"4064941117261",Datos!$F$2:$F$94,1)-SUMIFS(Datos!$P$2:$P$94,Datos!$B$2:$B$94,"4064941117261",Datos!$F$2:$F$94,1) -> 78 | M7: =SUMIFS(Datos!$J$2:$J$94,Datos!$B$2:$B$94,"4064941117261",Datos!$F$2:$F$94,1)-SUMIFS(Datos!$Q$2:$Q$94,Datos!$B$2:$B$94,"4064941117261",Datos!$F$2:$F$94,1) -> 0 | N7: =SUMIFS(Datos!$K$2:$K$94,Datos!$B$2:$B$94,"4064941117261",Datos!$F$2:$F$94,1)-SUMIFS(Datos!$R$2:$R$94,Datos!$B$2:$B$94,"4064941117261",Datos!$F$2:$F$94,1) -> 0 | O7: =H7-L7-M7-N7 -> 15 | P7: =SUMIFS(Datos!$I$2:$I$94,Datos!$B$2:$B$94,"4064941117261",Datos!$F$2:$F$94,1) -> 1222 | Q7: =P7-G7 -> -15
A8: Accesories (00006010) | B8: 4064941039655 | C8: KJ MU OTH ACC PENC SHARP n/a FY21 IV | D8: Sistema | E8: =SUMIFS(Datos!$T$2:$T$94,Datos!$B$2:$B$94,"4064941039655",Datos!$F$2:$F$94,1) -> 1885 | F8: =SUMIFS(Datos!$O$2:$O$94,Datos!$B$2:$B$94,"4064941039655",Datos!$F$2:$F$94,1) -> 935 | G8: =SUMIFS(Datos!$H$2:$H$94,Datos!$B$2:$B$94,"4064941039655",Datos!$F$2:$F$94,1) -> 974 | H8: =G8-F8 -> 39 | I8: =IFERROR(G8/F8-1,"") -> 0.04171123 | J8: =G8-E8 -> -911 | K8: =IFERROR(G8/E8-1,"") -> -0.48328912 | L8: =SUMIFS(Datos!$I$2:$I$94,Datos!$B$2:$B$94,"4064941039655",Datos!$F$2:$F$94,1)-SUMIFS(Datos!$P$2:$P$94,Datos!$B$2:$B$94,"4064941039655",Datos!$F$2:$F$94,1) -> 27 | M8: =SUMIFS(Datos!$J$2:$J$94,Datos!$B$2:$B$94,"4064941039655",Datos!$F$2:$F$94,1)-SUMIFS(Datos!$Q$2:$Q$94,Datos!$B$2:$B$94,"4064941039655",Datos!$F$2:$F$94,1) -> 0 | N8: =SUMIFS(Datos!$K$2:$K$94,Datos!$B$2:$B$94,"4064941039655",Datos!$F$2:$F$94,1)-SUMIFS(Datos!$R$2:$R$94,Datos!$B$2:$B$94,"4064941039655",Datos!$F$2:$F$94,1) -> 0 | O8: =H8-L8-M8-N8 -> 12 | P8: =SUMIFS(Datos!$I$2:$I$94,Datos!$B$2:$B$94,"4064941039655",Datos!$F$2:$F$94,1) -> 962 | Q8: =P8-G8 -> -12
A9: Face Multi (00006011) | B9: 4064941192046 | C9: KJ MU FACE ML UNVL BLSH PINCEAU04 IV | D9: Manual | E9: =SUMIFS(Datos!$T$2:$T$94,Datos!$B$2:$B$94,"4064941192046",Datos!$F$2:$F$94,1) -> 8571 | F9: =SUMIFS(Datos!$O$2:$O$94,Datos!$B$2:$B$94,"4064941192046",Datos!$F$2:$F$94,1) -> 6500 | G9: =SUMIFS(Datos!$H$2:$H$94,Datos!$B$2:$B$94,"4064941192046",Datos!$F$2:$F$94,1) -> 6495 | H9: =G9-F9 -> -5 | I9: =IFERROR(G9/F9-1,"") -> -0.00076923077 | J9: =G9-E9 -> -2076 | K9: =IFERROR(G9/E9-1,"") -> -0.24221211 | L9: =SUMIFS(Datos!$I$2:$I$94,Datos!$B$2:$B$94,"4064941192046",Datos!$F$2:$F$94,1)-SUMIFS(Datos!$P$2:$P$94,Datos!$B$2:$B$94,"4064941192046",Datos!$F$2:$F$94,1) -> 6872 | M9: =SUMIFS(Datos!$J$2:$J$94,Datos!$B$2:$B$94,"4064941192046",Datos!$F$2:$F$94,1)-SUMIFS(Datos!$Q$2:$Q$94,Datos!$B$2:$B$94,"4064941192046",Datos!$F$2:$F$94,1) -> 0 | N9: =SUMIFS(Datos!$K$2:$K$94,Datos!$B$2:$B$94,"4064941192046",Datos!$F$2:$F$94,1)-SUMIFS(Datos!$R$2:$R$94,Datos!$B$2:$B$94,"4064941192046",Datos!$F$2:$F$94,1) -> 0 | O9: =H9-L9-M9-N9 -> -6877 | P9: =SUMIFS(Datos!$I$2:$I$94,Datos!$B$2:$B$94,"4064941192046",Datos!$F$2:$F$94,1) -> 11105 | Q9: =P9-G9 -> 4610
A10: Face Multi (00006011) | B10: 4064941192060 | C10: KJ MU FACE ML BRUSH PRS SCLP CMPLN 05 IV | D10: Manual | E10: =SUMIFS(Datos!$T$2:$T$94,Datos!$B$2:$B$94,"4064941192060",Datos!$F$2:$F$94,1) -> 320 | F10: =SUMIFS(Datos!$O$2:$O$94,Datos!$B$2:$B$94,"4064941192060",Datos!$F$2:$F$94,1) -> 1278 | G10: =SUMIFS(Datos!$H$2:$H$94,Datos!$B$2:$B$94,"4064941192060",Datos!$F$2:$F$94,1) -> 1278 | H10: =G10-F10 -> 0 | I10: =IFERROR(G10/F10-1,"") -> 0 | J10: =G10-E10 -> 958 | K10: =IFERROR(G10/E10-1,"") -> 2.99375 | L10: =SUMIFS(Datos!$I$2:$I$94,Datos!$B$2:$B$94,"4064941192060",Datos!$F$2:$F$94,1)-SUMIFS(Datos!$P$2:$P$94,Datos!$B$2:$B$94,"4064941192060",Datos!$F$2:$F$94,1) -> -5777 | M10: =SUMIFS(Datos!$J$2:$J$94,Datos!$B$2:$B$94,"4064941192060",Datos!$F$2:$F$94,1)-SUMIFS(Datos!$Q$2:$Q$94,Datos!$B$2:$B$94,"4064941192060",Datos!$F$2:$F$94,1) -> 0 | N10: =SUMIFS(Datos!$K$2:$K$94,Datos!$B$2:$B$94,"4064941192060",Datos!$F$2:$F$94,1)-SUMIFS(Datos!$R$2:$R$94,Datos!$B$2:$B$94,"4064941192060",Datos!$F$2:$F$94,1) -> 0 | O10: =H10-L10-M10-N10 -> 5777 | P10: =SUMIFS(Datos!$I$2:$I$94,Datos!$B$2:$B$94,"4064941192060",Datos!$F$2:$F$94,1) -> 0 | Q10: =P10-G10 -> -1278
A11: Face Multi (00006011) | B11: 4064941200116 | C11: KJ MU FACE ML BRUSH KJCLIP REG IV | D11: Manual | E11: =SUMIFS(Datos!$T$2:$T$94,Datos!$B$2:$B$94,"4064941200116",Datos!$F$2:$F$94,1) -> 9582 | F11: =SUMIFS(Datos!$O$2:$O$94,Datos!$B$2:$B$94,"4064941200116",Datos!$F$2:$F$94,1) -> 1415 | G11: =SUMIFS(Datos!$H$2:$H$94,Datos!$B$2:$B$94,"4064941200116",Datos!$F$2:$F$94,1) -> 1415 | H11: =G11-F11 -> 0 | I11: =IFERROR(G11/F11-1,"") -> 0 | J11: =G11-E11 -> -8167 | K11: =IFERROR(G11/E11-1,"") -> -0.85232728 | L11: =SUMIFS(Datos!$I$2:$I$94,Datos!$B$2:$B$94,"4064941200116",Datos!$F$2:$F$94,1)-SUMIFS(Datos!$P$2:$P$94,Datos!$B$2:$B$94,"4064941200116",Datos!$F$2:$F$94,1) -> -1677 | M11: =SUMIFS(Datos!$J$2:$J$94,Datos!$B$2:$B$94,"4064941200116",Datos!$F$2:$F$94,1)-SUMIFS(Datos!$Q$2:$Q$94,Datos!$B$2:$B$94,"4064941200116",Datos!$F$2:$F$94,1) -> 0 | N11: =SUMIFS(Datos!$K$2:$K$94,Datos!$B$2:$B$94,"4064941200116",Datos!$F$2:$F$94,1)-SUMIFS(Datos!$R$2:$R$94,Datos!$B$2:$B$94,"4064941200116",Datos!$F$2:$F$94,1) -> 0 | O11: =H11-L11-M11-N11 -> 1677 | P11: =SUMIFS(Datos!$I$2:$I$94,Datos!$B$2:$B$94,"4064941200116",Datos!$F$2:$F$94,1) -> 29 | Q11: =P11-G11 -> -1386
A12: Kylie Eye Brushes (00006121) | B12: 4064941039662 | C12: KJ MU OTH ACC BRUSH n/a BROW FY21 IV | D12: Sistema | E12: =SUMIFS(Datos!$T$2:$T$94,Datos!$B$2:$B$94,"4064941039662",Datos!$F$2:$F$94,1) -> 139 | F12: =SUMIFS(Datos!$O$2:$O$94,Datos!$B$2:$B$94,"4064941039662",Datos!$F$2:$F$94,1) -> 0 | G12: =SUMIFS(Datos!$H$2:$H$94,Datos!$B$2:$B$94,"4064941039662",Datos!$F$2:$F$94,1) -> 0 | H12: =G12-F12 -> 0 | I12: =IFERROR(G12/F12-1,"") | J12: =G12-E12 -> -139 | K12: =IFERROR(G12/E12-1,"") -> -1 | L12: =SUMIFS(Datos!$I$2:$I$94,Datos!$B$2:$B$94,"4064941039662",Datos!$F$2:$F$94,1)-SUMIFS(Datos!$P$2:$P$94,Datos!$B$2:$B$94,"4064941039662",Datos!$F$2:$F$94,1) -> 0 | M12: =SUMIFS(Datos!$J$2:$J$94,Datos!$B$2:$B$94,"4064941039662",Datos!$F$2:$F$94,1)-SUMIFS(Datos!$Q$2:$Q$94,Datos!$B$2:$B$94,"4064941039662",Datos!$F$2:$F$94,1) -> 0 | N12: =SUMIFS(Datos!$K$2:$K$94,Datos!$B$2:$B$94,"4064941039662",Datos!$F$2:$F$94,1)-SUMIFS(Datos!$R$2:$R$94,Datos!$B$2:$B$94,"4064941039662",Datos!$F$2:$F$94,1) -> 0 | O12: =H12-L12-M12-N12 -> 0 | P12: =SUMIFS(Datos!$I$2:$I$94,Datos!$B$2:$B$94,"4064941039662",Datos!$F$2:$F$94,1) -> 0 | Q12: =P12-G12 -> 0
A13: TOTAL | E13: =SUM(E5:E12) -> 56438 | F13: =SUM(F5:F12) -> 40721 | G13: =SUM(G5:G12) -> 38682 | H13: =SUM(H5:H12) -> -2039 | I13: =IFERROR(G13/F13-1,"") -> -0.050072444 | J13: =SUM(J5:J12) -> -17756 | K13: =IFERROR(G13/E13-1,"") -> -0.31461072 | L13: =SUM(L5:L12) -> -2711 | M13: =SUM(M5:M12) -> -2000 | N13: =SUM(N5:N12) -> 1211 | O13: =SUM(O5:O12) -> 1461 | P13: =SUM(P5:P12) -> 39698 | Q13: =SUM(Q5:Q12) -> 1016

Sheet EAN x Mes
A1: Matriz EAN x Mes
A2: Consensus - Final en unidades. Horizonte 2026.M09 - 2027.M04.
A4: A. Δ vs ciclo pasado (W35 - W34)
A5: EAN | B5: Planning Item Description | C5: 2026.M09 | D5: 2026.M10 | E5: 2026.M11 | F5: 2026.M12 | G5: 2027.M01 | H5: 2027.M02 | I5: 2027.M03 | J5: 2027.M04 | K5: Total
A6: 4064941161349 | B6: KJ MU OTH ACC TINT BRUSH PINCEAU 03 IV | C6: =SUMIFS(Datos!$H$2:$H$94,Datos!$B$2:$B$94,"4064941161349",Datos!$D$2:$D$94,"2026.M09")-SUMIFS(Datos!$O$2:$O$94,Datos!$B$2:$B$94,"4064941161349",Datos!$D$2:$D$94,"2026.M09") -> 864 | D6: =SUMIFS(Datos!$H$2:$H$94,Datos!$B$2:$B$94,"4064941161349",Datos!$D$2:$D$94,"2026.M10")-SUMIFS(Datos!$O$2:$O$94,Datos!$B$2:$B$94,"4064941161349",Datos!$D$2:$D$94,"2026.M10") -> -962 | E6: =SUMIFS(Datos!$H$2:$H$94,Datos!$B$2:$B$94,"4064941161349",Datos!$D$2:$D$94,"2026.M11")-SUMIFS(Datos!$O$2:$O$94,Datos!$B$2:$B$94,"4064941161349",Datos!$D$2:$D$94,"2026.M11") -> 97 | F6: =SUMIFS(Datos!$H$2:$H$94,Datos!$B$2:$B$94,"4064941161349",Datos!$D$2:$D$94,"2026.M12")-SUMIFS(Datos!$O$2:$O$94,Datos!$B$2:$B$94,"4064941161349",Datos!$D$2:$D$94,"2026.M12") -> 12 | G6: =SUMIFS(Datos!$H$2:$H$94,Datos!$B$2:$B$94,"4064941161349",Datos!$D$2:$D$94,"2027.M01")-SUMIFS(Datos!$O$2:$O$94,Datos!$B$2:$B$94,"4064941161349",Datos!$D$2:$D$94,"2027.M01") -> -50 | H6: =SUMIFS(Datos!$H$2:$H$94,Datos!$B$2:$B$94,"4064941161349",Datos!$D$2:$D$94,"2027.M02")-SUMIFS(Datos!$O$2:$O$94,Datos!$B$2:$B$94,"4064941161349",Datos!$D$2:$D$94,"2027.M02") -> 659 | I6: =SUMIFS(Datos!$H$2:$H$94,Datos!$B$2:$B$94,"4064941161349",Datos!$D$2:$D$94,"2027.M03")-SUMIFS(Datos!$O$2:$O$94,Datos!$B$2:$B$94,"4064941161349",Datos!$D$2:$D$94,"2027.M03") -> -1905 | J6: =SUMIFS(Datos!$H$2:$H$94,Datos!$B$2:$B$94,"4064941161349",Datos!$D$2:$D$94,"2027.M04")-SUMIFS(Datos!$O$2:$O$94,Datos!$B$2:$B$94,"4064941161349",Datos!$D$2:$D$94,"2027.M04") -> -1223 | K6: =SUM(C6:J6) -> -2508
A7: 4064941117254 | B7: KJ MU OTH ACC BRUSH CONCE BRUSH IV | C7: =SUMIFS(Datos!$H$2:$H$94,Datos!$B$2:$B$94,"4064941117254",Datos!$D$2:$D$94,"2026.M09")-SUMIFS(Datos!$O$2:$O$94,Datos!$B$2:$B$94,"4064941117254",Datos!$D$2:$D$94,"2026.M09") -> 544 | D7: =SUMIFS(Datos!$H$2:$H$94,Datos!$B$2:$B$94,"4064941117254",Datos!$D$2:$D$94,"2026.M10")-SUMIFS(Datos!$O$2:$O$94,Datos!$B$2:$B$94,"4064941117254",Datos!$D$2:$D$94,"2026.M10") -> -277 | E7: =SUMIFS(Datos!$H$2:$H$94,Datos!$B$2:$B$94,"4064941117254",Datos!$D$2:$D$94,"2026.M11")-SUMIFS(Datos!$O$2:$O$94,Datos!$B$2:$B$94,"4064941117254",Datos!$D$2:$D$94,"2026.M11") -> 273 | F7: =SUMIFS(Datos!$H$2:$H$94,Datos!$B$2:$B$94,"4064941117254",Datos!$D$2:$D$94,"2026.M12")-SUMIFS(Datos!$O$2:$O$94,Datos!$B$2:$B$94,"4064941117254",Datos!$D$2:$D$94,"2026.M12") -> 542 | G7: =SUMIFS(Datos!$H$2:$H$94,Datos!$B$2:$B$94,"4064941117254",Datos!$D$2:$D$94,"2027.M01")-SUMIFS(Datos!$O$2:$O$94,Datos!$B$2:$B$94,"4064941117254",Datos!$D$2:$D$94,"2027.M01") -> 179 | H7: =SUMIFS(Datos!$H$2:$H$94,Datos!$B$2:$B$94,"4064941117254",Datos!$D$2:$D$94,"2027.M02")-SUMIFS(Datos!$O$2:$O$94,Datos!$B$2:$B$94,"4064941117254",Datos!$D$2:$D$94,"2027.M02") -> -1007 | I7: =SUMIFS(Datos!$H$2:$H$94,Datos!$B$2:$B$94,"4064941117254",Datos!$D$2:$D$94,"2027.M03")-SUMIFS(Datos!$O$2:$O$94,Datos!$B$2:$B$94,"4064941117254",Datos!$D$2:$D$94,"2027.M03") -> -3 | J7: =SUMIFS(Datos!$H$2:$H$94,Datos!$B$2:$B$94,"4064941117254",Datos!$D$2:$D$94,"2027.M04")-SUMIFS(Datos!$O$2:$O$94,Datos!$B$2:$B$94,"4064941117254",Datos!$D$2:$D$94,"2027.M04") -> 91 | K7: =SUM(C7:J7) -> 342
A8: 4064941117261 | B8: KJ MU OTH ACC RG BRUSH FOUND 23IV | C8: =SUMIFS(Datos!$H$2:$H$94,Datos!$B$2:$B$94,"4064941117261",Datos!$D$2:$D$94,"2026.M09")-SUMIFS(Datos!$O$2:$O$94,Datos!$B$2:$B$94,"4064941117261",Datos!$D$2:$D$94,"2026.M09") -> 103 | D8: =SUMIFS(Datos!$H$2:$H$94,Datos!$B$2:$B$94,"4064941117261",Datos!$D$2:$D$94,"2026.M10")-SUMIFS(Datos!$O$2:$O$94,Datos!$B$2:$B$94,"4064941117261",Datos!$D$2:$D$94,"2026.M10") -> -34 | E8: =SUMIFS(Datos!$H$2:$H$94,Datos!$B$2:$B$94,"4064941117261",Datos!$D$2:$D$94,"2026.M11")-SUMIFS(Datos!$O$2:$O$94,Datos!$B$2:$B$94,"4064941117261",Datos!$D$2:$D$94,"2026.M11") -> 18 | F8: =SUMIFS(Datos!$H$2:$H$94,Datos!$B$2:$B$94,"4064941117261",Datos!$D$2:$D$94,"2026.M12")-SUMIFS(Datos!$O$2:$O$94,Datos!$B$2:$B$94,"4064941117261",Datos!$D$2:$D$94,"2026.M12") -> 28 | G8: =SUMIFS(Datos!$H$2:$H$94,Datos!$B$2:$B$94,"4064941117261",Datos!$D$2:$D$94,"2027.M01")-SUMIFS(Datos!$O$2:$O$94,Datos!$B$2:$B$94,"4064941117261",Datos!$D$2:$D$94,"2027.M01") -> -4 | H8: =SUMIFS(Datos!$H$2:$H$94,Datos!$B$2:$B$94,"4064941117261",Datos!$D$2:$D$94,"2027.M02")-SUMIFS(Datos!$O$2:$O$94,Datos!$B$2:$B$94,"4064941117261",Datos!$D$2:$D$94,"2027.M02") -> 20 | I8: =SUMIFS(Datos!$H$2:$H$94,Datos!$B$2:$B$94,"4064941117261",Datos!$D$2:$D$94,"2027.M03")-SUMIFS(Datos!$O$2:$O$94,Datos!$B$2:$B$94,"4064941117261",Datos!$D$2:$D$94,"2027.M03") -> 13 | J8: =SUMIFS(Datos!$H$2:$H$94,Datos!$B$2:$B$94,"4064941117261",Datos!$D$2:$D$94,"2027.M04")-SUMIFS(Datos!$O$2:$O$94,Datos!$B$2:$B$94,"4064941117261",Datos!$D$2:$D$94,"2027.M04") -> -51 | K8: =SUM(C8:J8) -> 93
A9: 4064941039655 | B9: KJ MU OTH ACC PENC SHARP n/a FY21 IV | C9: =SUMIFS(Datos!$H$2:$H$94,Datos!$B$2:$B$94,"4064941039655",Datos!$D$2:$D$94,"2026.M09")-SUMIFS(Datos!$O$2:$O$94,Datos!$B$2:$B$94,"4064941039655",Datos!$D$2:$D$94,"2026.M09") -> 77 | D9: =SUMIFS(Datos!$H$2:$H$94,Datos!$B$2:$B$94,"4064941039655",Datos!$D$2:$D$94,"2026.M10")-SUMIFS(Datos!$O$2:$O$94,Datos!$B$2:$B$94,"4064941039655",Datos!$D$2:$D$94,"2026.M10") -> -28 | E9: =SUMIFS(Datos!$H$2:$H$94,Datos!$B$2:$B$94,"4064941039655",Datos!$D$2:$D$94,"2026.M11")-SUMIFS(Datos!$O$2:$O$94,Datos!$B$2:$B$94,"4064941039655",Datos!$D$2:$D$94,"2026.M11") -> 4 | F9: =SUMIFS(Datos!$H$2:$H$94,Datos!$B$2:$B$94,"4064941039655",Datos!$D$2:$D$94,"2026.M12")-SUMIFS(Datos!$O$2:$O$94,Datos!$B$2:$B$94,"4064941039655",Datos!$D$2:$D$94,"2026.M12") -> 18 | G9: =SUMIFS(Datos!$H$2:$H$94,Datos!$B$2:$B$94,"4064941039655",Datos!$D$2:$D$94,"2027.M01")-SUMIFS(Datos!$O$2:$O$94,Datos!$B$2:$B$94,"4064941039655",Datos!$D$2:$D$94,"2027.M01") -> -5 | H9: =SUMIFS(Datos!$H$2:$H$94,Datos!$B$2:$B$94,"4064941039655",Datos!$D$2:$D$94,"2027.M02")-SUMIFS(Datos!$O$2:$O$94,Datos!$B$2:$B$94,"4064941039655",Datos!$D$2:$D$94,"2027.M02") -> 12 | I9: =SUMIFS(Datos!$H$2:$H$94,Datos!$B$2:$B$94,"4064941039655",Datos!$D$2:$D$94,"2027.M03")-SUMIFS(Datos!$O$2:$O$94,Datos!$B$2:$B$94,"4064941039655",Datos!$D$2:$D$94,"2027.M03") -> 8 | J9: =SUMIFS(Datos!$H$2:$H$94,Datos!$B$2:$B$94,"4064941039655",Datos!$D$2:$D$94,"2027.M04")-SUMIFS(Datos!$O$2:$O$94,Datos!$B$2:$B$94,"4064941039655",Datos!$D$2:$D$94,"2027.M04") -> -47 | K9: =SUM(C9:J9) -> 39
A10: 4064941192046 | B10: KJ MU FACE ML UNVL BLSH PINCEAU04 IV | C10: =SUMIFS(Datos!$H$2:$H$94,Datos!$B$2:$B$94,"4064941192046",Datos!$D$2:$D$94,"2026.M09")-SUMIFS(Datos!$O$2:$O$94,Datos!$B$2:$B$94,"4064941192046",Datos!$D$2:$D$94,"2026.M09") -> -5 | D10: =SUMIFS(Datos!$H$2:$H$94,Datos!$B$2:$B$94,"4064941192046",Datos!$D$2:$D$94,"2026.M10")-SUMIFS(Datos!$O$2:$O$94,Datos!$B$2:$B$94,"4064941192046",Datos!$D$2:$D$94,"2026.M10") -> 0 | E10: =SUMIFS(Datos!$H$2:$H$94,Datos!$B$2:$B$94,"4064941192046",Datos!$D$2:$D$94,"2026.M11")-SUMIFS(Datos!$O$2:$O$94,Datos!$B$2:$B$94,"4064941192046",Datos!$D$2:$D$94,"2026.M11") -> 0 | F10: =SUMIFS(Datos!$H$2:$H$94,Datos!$B$2:$B$94,"4064941192046",Datos!$D$2:$D$94,"2026.M12")-SUMIFS(Datos!$O$2:$O$94,Datos!$B$2:$B$94,"4064941192046",Datos!$D$2:$D$94,"2026.M12") -> 0 | G10: =SUMIFS(Datos!$H$2:$H$94,Datos!$B$2:$B$94,"4064941192046",Datos!$D$2:$D$94,"2027.M01")-SUMIFS(Datos!$O$2:$O$94,Datos!$B$2:$B$94,"4064941192046",Datos!$D$2:$D$94,"2027.M01") -> 0 | H10: =SUMIFS(Datos!$H$2:$H$94,Datos!$B$2:$B$94,"4064941192046",Datos!$D$2:$D$94,"2027.M02")-SUMIFS(Datos!$O$2:$O$94,Datos!$B$2:$B$94,"4064941192046",Datos!$D$2:$D$94,"2027.M02") -> 0 | I10: =SUMIFS(Datos!$H$2:$H$94,Datos!$B$2:$B$94,"4064941192046",Datos!$D$2:$D$94,"2027.M03")-SUMIFS(Datos!$O$2:$O$94,Datos!$B$2:$B$94,"4064941192046",Datos!$D$2:$D$94,"2027.M03") -> 0 | J10: =SUMIFS(Datos!$H$2:$H$94,Datos!$B$2:$B$94,"4064941192046",Datos!$D$2:$D$94,"2027.M04")-SUMIFS(Datos!$O$2:$O$94,Datos!$B$2:$B$94,"4064941192046",Datos!$D$2:$D$94,"2027.M04") -> 0 | K10: =SUM(C10:J10) -> -5
A11: 4064941192060 | B11: KJ MU FACE ML BRUSH PRS SCLP CMPLN 05 IV | C11: =SUMIFS(Datos!$H$2:$H$94,Datos!$B$2:$B$94,"4064941192060",Datos!$D$2:$D$94,"2026.M09")-SUMIFS(Datos!$O$2:$O$94,Datos!$B$2:$B$94,"4064941192060",Datos!$D$2:$D$94,"2026.M09") -> 0 | D11: =SUMIFS(Datos!$H$2:$H$94,Datos!$B$2:$B$94,"4064941192060",Datos!$D$2:$D$94,"2026.M10")-SUMIFS(Datos!$O$2:$O$94,Datos!$B$2:$B$94,"4064941192060",Datos!$D$2:$D$94,"2026.M10") -> 0 | E11: =SUMIFS(Datos!$H$2:$H$94,Datos!$B$2:$B$94,"4064941192060",Datos!$D$2:$D$94,"2026.M11")-SUMIFS(Datos!$O$2:$O$94,Datos!$B$2:$B$94,"4064941192060",Datos!$D$2:$D$94,"2026.M11") -> 0 | F11: =SUMIFS(Datos!$H$2:$H$94,Datos!$B$2:$B$94,"4064941192060",Datos!$D$2:$D$94,"2026.M12")-SUMIFS(Datos!$O$2:$O$94,Datos!$B$2:$B$94,"4064941192060",Datos!$D$2:$D$94,"2026.M12") -> 0 | G11: =SUMIFS(Datos!$H$2:$H$94,Datos!$B$2:$B$94,"4064941192060",Datos!$D$2:$D$94,"2027.M01")-SUMIFS(Datos!$O$2:$O$94,Datos!$B$2:$B$94,"4064941192060",Datos!$D$2:$D$94,"2027.M01") -> 0 | H11: =SUMIFS(Datos!$H$2:$H$94,Datos!$B$2:$B$94,"4064941192060",Datos!$D$2:$D$94,"2027.M02")-SUMIFS(Datos!$O$2:$O$94,Datos!$B$2:$B$94,"4064941192060",Datos!$D$2:$D$94,"2027.M02") -> 0 | I11: =SUMIFS(Datos!$H$2:$H$94,Datos!$B$2:$B$94,"4064941192060",Datos!$D$2:$D$94,"2027.M03")-SUMIFS(Datos!$O$2:$O$94,Datos!$B$2:$B$94,"4064941192060",Datos!$D$2:$D$94,"2027.M03") -> 0 | J11: =SUMIFS(Datos!$H$2:$H$94,Datos!$B$2:$B$94,"4064941192060",Datos!$D$2:$D$94,"2027.M04")-SUMIFS(Datos!$O$2:$O$94,Datos!$B$2:$B$94,"4064941192060",Datos!$D$2:$D$94,"2027.M04") -> 0 | K11: =SUM(C11:J11) -> 0
A12: 4064941200116 | B12: KJ MU FACE ML BRUSH KJCLIP REG IV | C12: =SUMIFS(Datos!$H$2:$H$94,Datos!$B$2:$B$94,"4064941200116",Datos!$D$2:$D$94,"2026.M09")-SUMIFS(Datos!$O$2:$O$94,Datos!$B$2:$B$94,"4064941200116",Datos!$D$2:$D$94,"2026.M09") -> 0 | D12: =SUMIFS(Datos!$H$2:$H$94,Datos!$B$2:$B$94,"4064941200116",Datos!$D$2:$D$94,"2026.M10")-SUMIFS(Datos!$O$2:$O$94,Datos!$B$2:$B$94,"4064941200116",Datos!$D$2:$D$94,"2026.M10") -> 0 | E12: =SUMIFS(Datos!$H$2:$H$94,Datos!$B$2:$B$94,"4064941200116",Datos!$D$2:$D$94,"2026.M11")-SUMIFS(Datos!$O$2:$O$94,Datos!$B$2:$B$94,"4064941200116",Datos!$D$2:$D$94,"2026.M11") -> 0 | F12: =SUMIFS(Datos!$H$2:$H$94,Datos!$B$2:$B$94,"4064941200116",Datos!$D$2:$D$94,"2026.M12")-SUMIFS(Datos!$O$2:$O$94,Datos!$B$2:$B$94,"4064941200116",Datos!$D$2:$D$94,"2026.M12") -> 0 | G12: =SUMIFS(Datos!$H$2:$H$94,Datos!$B$2:$B$94,"4064941200116",Datos!$D$2:$D$94,"2027.M01")-SUMIFS(Datos!$O$2:$O$94,Datos!$B$2:$B$94,"4064941200116",Datos!$D$2:$D$94,"2027.M01") -> 0 | H12: =SUMIFS(Datos!$H$2:$H$94,Datos!$B$2:$B$94,"4064941200116",Datos!$D$2:$D$94,"2027.M02")-SUMIFS(Datos!$O$2:$O$94,Datos!$B$2:$B$94,"4064941200116",Datos!$D$2:$D$94,"2027.M02") -> 0 | I12: =SUMIFS(Datos!$H$2:$H$94,Datos!$B$2:$B$94,"4064941200116",Datos!$D$2:$D$94,"2027.M03")-SUMIFS(Datos!$O$2:$O$94,Datos!$B$2:$B$94,"4064941200116",Datos!$D$2:$D$94,"2027.M03") -> 0 | J12: =SUMIFS(Datos!$H$2:$H$94,Datos!$B$2:$B$94,"4064941200116",Datos!$D$2:$D$94,"2027.M04")-SUMIFS(Datos!$O$2:$O$94,Datos!$B$2:$B$94,"4064941200116",Datos!$D$2:$D$94,"2027.M04") -> 0 | K12: =SUM(C12:J12) -> 0
A13: 4064941039662 | B13: KJ MU OTH ACC BRUSH n/a BROW FY21 IV | C13: =SUMIFS(Datos!$H$2:$H$94,Datos!$B$2:$B$94,"4064941039662",Datos!$D$2:$D$94,"2026.M09")-SUMIFS(Datos!$O$2:$O$94,Datos!$B$2:$B$94,"4064941039662",Datos!$D$2:$D$94,"2026.M09") -> 0 | D13: =SUMIFS(Datos!$H$2:$H$94,Datos!$B$2:$B$94,"4064941039662",Datos!$D$2:$D$94,"2026.M10")-SUMIFS(Datos!$O$2:$O$94,Datos!$B$2:$B$94,"4064941039662",Datos!$D$2:$D$94,"2026.M10") -> 0 | E13: =SUMIFS(Datos!$H$2:$H$94,Datos!$B$2:$B$94,"4064941039662",Datos!$D$2:$D$94,"2026.M11")-SUMIFS(Datos!$O$2:$O$94,Datos!$B$2:$B$94,"4064941039662",Datos!$D$2:$D$94,"2026.M11") -> 0 | F13: =SUMIFS(Datos!$H$2:$H$94,Datos!$B$2:$B$94,"4064941039662",Datos!$D$2:$D$94,"2026.M12")-SUMIFS(Datos!$O$2:$O$94,Datos!$B$2:$B$94,"4064941039662",Datos!$D$2:$D$94,"2026.M12") -> 0 | G13: =SUMIFS(Datos!$H$2:$H$94,Datos!$B$2:$B$94,"4064941039662",Datos!$D$2:$D$94,"2027.M01")-SUMIFS(Datos!$O$2:$O$94,Datos!$B$2:$B$94,"4064941039662",Datos!$D$2:$D$94,"2027.M01") -> 0 | H13: =SUMIFS(Datos!$H$2:$H$94,Datos!$B$2:$B$94,"4064941039662",Datos!$D$2:$D$94,"2027.M02")-SUMIFS(Datos!$O$2:$O$94,Datos!$B$2:$B$94,"4064941039662",Datos!$D$2:$D$94,"2027.M02") -> 0 | I13: =SUMIFS(Datos!$H$2:$H$94,Datos!$B$2:$B$94,"4064941039662",Datos!$D$2:$D$94,"2027.M03")-SUMIFS(Datos!$O$2:$O$94,Datos!$B$2:$B$94,"4064941039662",Datos!$D$2:$D$94,"2027.M03") -> 0 | J13: =SUMIFS(Datos!$H$2:$H$94,Datos!$B$2:$B$94,"4064941039662",Datos!$D$2:$D$94,"2027.M04")-SUMIFS(Datos!$O$2:$O$94,Datos!$B$2:$B$94,"4064941039662",Datos!$D$2:$D$94,"2027.M04") -> 0 | K13: =SUM(C13:J13) -> 0
A14: TOTAL | C14: =SUM(C6:C13) -> 1583 | D14: =SUM(D6:D13) -> -1301 | E14: =SUM(E6:E13) -> 392 | F14: =SUM(F6:F13) -> 600 | G14: =SUM(G6:G13) -> 120 | H14: =SUM(H6:H13) -> -316 | I14: =SUM(I6:I13) -> -1887 | J14: =SUM(J6:J13) -> -1230 | K14: =SUM(K6:K13) -> -2039
A17: B. Consensus W35 (este ciclo)
A18: EAN | B18: Planning Item Description | C18: 2026.M09 | D18: 2026.M10 | E18: 2026.M11 | F18: 2026.M12 | G18: 2027.M01 | H18: 2027.M02 | I18: 2027.M03 | J18: 2027.M04 | K18: Total
A19: 4064941161349 | B19: KJ MU OTH ACC TINT BRUSH PINCEAU 03 IV | C19: =SUMIFS(Datos!$H$2:$H$94,Datos!$B$2:$B$94,"4064941161349",Datos!$D$2:$D$94,"2026.M09") -> 4157 | D19: =SUMIFS(Datos!$H$2:$H$94,Datos!$B$2:$B$94,"4064941161349",Datos!$D$2:$D$94,"2026.M10") -> 1944 | E19: =SUMIFS(Datos!$H$2:$H$94,Datos!$B$2:$B$94,"4064941161349",Datos!$D$2:$D$94,"2026.M11") -> 2488 | F19: =SUMIFS(Datos!$H$2:$H$94,Datos!$B$2:$B$94,"4064941161349",Datos!$D$2:$D$94,"2026.M12") -> 2927 | G19: =SUMIFS(Datos!$H$2:$H$94,Datos!$B$2:$B$94,"4064941161349",Datos!$D$2:$D$94,"2027.M01") -> 2418 | H19: =SUMIFS(Datos!$H$2:$H$94,Datos!$B$2:$B$94,"4064941161349",Datos!$D$2:$D$94,"2027.M02") -> 3068 | I19: =SUMIFS(Datos!$H$2:$H$94,Datos!$B$2:$B$94,"4064941161349",Datos!$D$2:$D$94,"2027.M03") -> 3011 | J19: =SUMIFS(Datos!$H$2:$H$94,Datos!$B$2:$B$94,"4064941161349",Datos!$D$2:$D$94,"2027.M04") -> 1401 | K19: =SUM(C19:J19) -> 21414
A20: 4064941117254 | B20: KJ MU OTH ACC BRUSH CONCE BRUSH IV | C20: =SUMIFS(Datos!$H$2:$H$94,Datos!$B$2:$B$94,"4064941117254",Datos!$D$2:$D$94,"2026.M09") -> 997 | D20: =SUMIFS(Datos!$H$2:$H$94,Datos!$B$2:$B$94,"4064941117254",Datos!$D$2:$D$94,"2026.M10") -> 563 | E20: =SUMIFS(Datos!$H$2:$H$94,Datos!$B$2:$B$94,"4064941117254",Datos!$D$2:$D$94,"2026.M11") -> 710 | F20: =SUMIFS(Datos!$H$2:$H$94,Datos!$B$2:$B$94,"4064941117254",Datos!$D$2:$D$94,"2026.M12") -> 844 | G20: =SUMIFS(Datos!$H$2:$H$94,Datos!$B$2:$B$94,"4064941117254",Datos!$D$2:$D$94,"2027.M01") -> 633 | H20: =SUMIFS(Datos!$H$2:$H$94,Datos!$B$2:$B$94,"4064941117254",Datos!$D$2:$D$94,"2027.M02") -> 880 | I20: =SUMIFS(Datos!$H$2:$H$94,Datos!$B$2:$B$94,"4064941117254",Datos!$D$2:$D$94,"2027.M03") -> 824 | J20: =SUMIFS(Datos!$H$2:$H$94,Datos!$B$2:$B$94,"4064941117254",Datos!$D$2:$D$94,"2027.M04") -> 418 | K20: =SUM(C20:J20) -> 5869
A21: 4064941117261 | B21: KJ MU OTH ACC RG BRUSH FOUND 23IV | C21: =SUMIFS(Datos!$H$2:$H$94,Datos!$B$2:$B$94,"4064941117261",Datos!$D$2:$D$94,"2026.M09") -> 245 | D21: =SUMIFS(Datos!$H$2:$H$94,Datos!$B$2:$B$94,"4064941117261",Datos!$D$2:$D$94,"2026.M10") -> 112 | E21: =SUMIFS(Datos!$H$2:$H$94,Datos!$B$2:$B$94,"4064941117261",Datos!$D$2:$D$94,"2026.M11") -> 150 | F21: =SUMIFS(Datos!$H$2:$H$94,Datos!$B$2:$B$94,"4064941117261",Datos!$D$2:$D$94,"2026.M12") -> 174 | G21: =SUMIFS(Datos!$H$2:$H$94,Datos!$B$2:$B$94,"4064941117261",Datos!$D$2:$D$94,"2027.M01") -> 129 | H21: =SUMIFS(Datos!$H$2:$H$94,Datos!$B$2:$B$94,"4064941117261",Datos!$D$2:$D$94,"2027.M02") -> 176 | I21: =SUMIFS(Datos!$H$2:$H$94,Datos!$B$2:$B$94,"4064941117261",Datos!$D$2:$D$94,"2027.M03") -> 173 | J21: =SUMIFS(Datos!$H$2:$H$94,Datos!$B$2:$B$94,"4064941117261",Datos!$D$2:$D$94,"2027.M04") -> 78 | K21: =SUM(C21:J21) -> 1237
A22: 4064941039655 | B22: KJ MU OTH ACC PENC SHARP n/a FY21 IV | C22: =SUMIFS(Datos!$H$2:$H$94,Datos!$B$2:$B$94,"4064941039655",Datos!$D$2:$D$94,"2026.M09") -> 193 | D22: =SUMIFS(Datos!$H$2:$H$94,Datos!$B$2:$B$94,"4064941039655",Datos!$D$2:$D$94,"2026.M10") -> 88 | E22: =SUMIFS(Datos!$H$2:$H$94,Datos!$B$2:$B$94,"4064941039655",Datos!$D$2:$D$94,"2026.M11") -> 116 | F22: =SUMIFS(Datos!$H$2:$H$94,Datos!$B$2:$B$94,"4064941039655",Datos!$D$2:$D$94,"2026.M12") -> 138 | G22: =SUMIFS(Datos!$H$2:$H$94,Datos!$B$2:$B$94,"4064941039655",Datos!$D$2:$D$94,"2027.M01") -> 102 | H22: =SUMIFS(Datos!$H$2:$H$94,Datos!$B$2:$B$94,"4064941039655",Datos!$D$2:$D$94,"2027.M02") -> 140 | I22: =SUMIFS(Datos!$H$2:$H$94,Datos!$B$2:$B$94,"4064941039655",Datos!$D$2:$D$94,"2027.M03") -> 137 | J22: =SUMIFS(Datos!$H$2:$H$94,Datos!$B$2:$B$94,"4064941039655",Datos!$D$2:$D$94,"2027.M04") -> 60 | K22: =SUM(C22:J22) -> 974
A23: 4064941192046 | B23: KJ MU FACE ML UNVL BLSH PINCEAU04 IV | C23: =SUMIFS(Datos!$H$2:$H$94,Datos!$B$2:$B$94,"4064941192046",Datos!$D$2:$D$94,"2026.M09") -> 1995 | D23: =SUMIFS(Datos!$H$2:$H$94,Datos!$B$2:$B$94,"4064941192046",Datos!$D$2:$D$94,"2026.M10") -> 1000 | E23: =SUMIFS(Datos!$H$2:$H$94,Datos!$B$2:$B$94,"4064941192046",Datos!$D$2:$D$94,"2026.M11") -> 750 | F23: =SUMIFS(Datos!$H$2:$H$94,Datos!$B$2:$B$94,"4064941192046",Datos!$D$2:$D$94,"2026.M12") -> 750 | G23: =SUMIFS(Datos!$H$2:$H$94,Datos!$B$2:$B$94,"4064941192046",Datos!$D$2:$D$94,"2027.M01") -> 500 | H23: =SUMIFS(Datos!$H$2:$H$94,Datos!$B$2:$B$94,"4064941192046",Datos!$D$2:$D$94,"2027.M02") -> 500 | I23: =SUMIFS(Datos!$H$2:$H$94,Datos!$B$2:$B$94,"4064941192046",Datos!$D$2:$D$94,"2027.M03") -> 500 | J23: =SUMIFS(Datos!$H$2:$H$94,Datos!$B$2:$B$94,"4064941192046",Datos!$D$2:$D$94,"2027.M04") -> 500 | K23: =SUM(C23:J23) -> 6495
A24: 4064941192060 | B24: KJ MU FACE ML BRUSH PRS SCLP CMPLN 05 IV | C24: =SUMIFS(Datos!$H$2:$H$94,Datos!$B$2:$B$94,"4064941192060",Datos!$D$2:$D$94,"2026.M09") -> 212 | D24: =SUMIFS(Datos!$H$2:$H$94,Datos!$B$2:$B$94,"4064941192060",Datos!$D$2:$D$94,"2026.M10") -> 217 | E24: =SUMIFS(Datos!$H$2:$H$94,Datos!$B$2:$B$94,"4064941192060",Datos!$D$2:$D$94,"2026.M11") -> 212 | F24: =SUMIFS(Datos!$H$2:$H$94,Datos!$B$2:$B$94,"4064941192060",Datos!$D$2:$D$94,"2026.M12") -> 194 | G24: =SUMIFS(Datos!$H$2:$H$94,Datos!$B$2:$B$94,"4064941192060",Datos!$D$2:$D$94,"2027.M01") -> 194 | H24: =SUMIFS(Datos!$H$2:$H$94,Datos!$B$2:$B$94,"4064941192060",Datos!$D$2:$D$94,"2027.M02") -> 200 | I24: =SUMIFS(Datos!$H$2:$H$94,Datos!$B$2:$B$94,"4064941192060",Datos!$D$2:$D$94,"2027.M03") -> 49 | J24: =SUMIFS(Datos!$H$2:$H$94,Datos!$B$2:$B$94,"4064941192060",Datos!$D$2:$D$94,"2027.M04") -> 0 | K24: =SUM(C24:J24) -> 1278
A25: 4064941200116 | B25: KJ MU FACE ML BRUSH KJCLIP REG IV | C25: =SUMIFS(Datos!$H$2:$H$94,Datos!$B$2:$B$94,"4064941200116",Datos!$D$2:$D$94,"2026.M09") -> 193 | D25: =SUMIFS(Datos!$H$2:$H$94,Datos!$B$2:$B$94,"4064941200116",Datos!$D$2:$D$94,"2026.M10") -> 179 | E25: =SUMIFS(Datos!$H$2:$H$94,Datos!$B$2:$B$94,"4064941200116",Datos!$D$2:$D$94,"2026.M11") -> 266 | F25: =SUMIFS(Datos!$H$2:$H$94,Datos!$B$2:$B$94,"4064941200116",Datos!$D$2:$D$94,"2026.M12") -> 160 | G25: =SUMIFS(Datos!$H$2:$H$94,Datos!$B$2:$B$94,"4064941200116",Datos!$D$2:$D$94,"2027.M01") -> 167 | H25: =SUMIFS(Datos!$H$2:$H$94,Datos!$B$2:$B$94,"4064941200116",Datos!$D$2:$D$94,"2027.M02") -> 150 | I25: =SUMIFS(Datos!$H$2:$H$94,Datos!$B$2:$B$94,"4064941200116",Datos!$D$2:$D$94,"2027.M03") -> 150 | J25: =SUMIFS(Datos!$H$2:$H$94,Datos!$B$2:$B$94,"4064941200116",Datos!$D$2:$D$94,"2027.M04") -> 150 | K25: =SUM(C25:J25) -> 1415
A26: 4064941039662 | B26: KJ MU OTH ACC BRUSH n/a BROW FY21 IV | C26: =SUMIFS(Datos!$H$2:$H$94,Datos!$B$2:$B$94,"4064941039662",Datos!$D$2:$D$94,"2026.M09") -> 0 | D26: =SUMIFS(Datos!$H$2:$H$94,Datos!$B$2:$B$94,"4064941039662",Datos!$D$2:$D$94,"2026.M10") -> 0 | E26: =SUMIFS(Datos!$H$2:$H$94,Datos!$B$2:$B$94,"4064941039662",Datos!$D$2:$D$94,"2026.M11") -> 0 | F26: =SUMIFS(Datos!$H$2:$H$94,Datos!$B$2:$B$94,"4064941039662",Datos!$D$2:$D$94,"2026.M12") -> 0 | G26: =SUMIFS(Datos!$H$2:$H$94,Datos!$B$2:$B$94,"4064941039662",Datos!$D$2:$D$94,"2027.M01") -> 0 | H26: =SUMIFS(Datos!$H$2:$H$94,Datos!$B$2:$B$94,"4064941039662",Datos!$D$2:$D$94,"2027.M02") -> 0 | I26: =SUMIFS(Datos!$H$2:$H$94,Datos!$B$2:$B$94,"4064941039662",Datos!$D$2:$D$94,"2027.M03") -> 0 | J26: =SUMIFS(Datos!$H$2:$H$94,Datos!$B$2:$B$94,"4064941039662",Datos!$D$2:$D$94,"2027.M04") -> 0 | K26: =SUM(C26:J26) -> 0
A27: TOTAL | C27: =SUM(C19:C26) -> 7992 | D27: =SUM(D19:D26) -> 4103 | E27: =SUM(E19:E26) -> 4692 | F27: =SUM(F19:F26) -> 5187 | G27: =SUM(G19:G26) -> 4143 | H27: =SUM(H19:H26) -> 5114 | I27: =SUM(I19:I26) -> 4844 | J27: =SUM(J19:J26) -> 2607 | K27: =SUM(K19:K26) -> 38682
A30: C. Consensus W34 (ciclo pasado)
A31: EAN | B31: Planning Item Description | C31: 2026.M09 | D31: 2026.M10 | E31: 2026.M11 | F31: 2026.M12 | G31: 2027.M01 | H31: 2027.M02 | I31: 2027.M03 | J31: 2027.M04 | K31: Total
A32: 4064941161349 | B32: KJ MU OTH ACC TINT BRUSH PINCEAU 03 IV | C32: =SUMIFS(Datos!$O$2:$O$94,Datos!$B$2:$B$94,"4064941161349",Datos!$D$2:$D$94,"2026.M09") -> 3293 | D32: =SUMIFS(Datos!$O$2:$O$94,Datos!$B$2:$B$94,"4064941161349",Datos!$D$2:$D$94,"2026.M10") -> 2906 | E32: =SUMIFS(Datos!$O$2:$O$94,Datos!$B$2:$B$94,"4064941161349",Datos!$D$2:$D$94,"2026.M11") -> 2391 | F32: =SUMIFS(Datos!$O$2:$O$94,Datos!$B$2:$B$94,"4064941161349",Datos!$D$2:$D$94,"2026.M12") -> 2915 | G32: =SUMIFS(Datos!$O$2:$O$94,Datos!$B$2:$B$94,"4064941161349",Datos!$D$2:$D$94,"2027.M01") -> 2468 | H32: =SUMIFS(Datos!$O$2:$O$94,Datos!$B$2:$B$94,"4064941161349",Datos!$D$2:$D$94,"2027.M02") -> 2409 | I32: =SUMIFS(Datos!$O$2:$O$94,Datos!$B$2:$B$94,"4064941161349",Datos!$D$2:$D$94,"2027.M03") -> 4916 | J32: =SUMIFS(Datos!$O$2:$O$94,Datos!$B$2:$B$94,"4064941161349",Datos!$D$2:$D$94,"2027.M04") -> 2624 | K32: =SUM(C32:J32) -> 23922
A33: 4064941117254 | B33: KJ MU OTH ACC BRUSH CONCE BRUSH IV | C33: =SUMIFS(Datos!$O$2:$O$94,Datos!$B$2:$B$94,"4064941117254",Datos!$D$2:$D$94,"2026.M09") -> 453 | D33: =SUMIFS(Datos!$O$2:$O$94,Datos!$B$2:$B$94,"4064941117254",Datos!$D$2:$D$94,"2026.M10") -> 840 | E33: =SUMIFS(Datos!$O$2:$O$94,Datos!$B$2:$B$94,"4064941117254",Datos!$D$2:$D$94,"2026.M11") -> 437 | F33: =SUMIFS(Datos!$O$2:$O$94,Datos!$B$2:$B$94,"4064941117254",Datos!$D$2:$D$94,"2026.M12") -> 302 | G33: =SUMIFS(Datos!$O$2:$O$94,Datos!$B$2:$B$94,"4064941117254",Datos!$D$2:$D$94,"2027.M01") -> 454 | H33: =SUMIFS(Datos!$O$2:$O$94,Datos!$B$2:$B$94,"4064941117254",Datos!$D$2:$D$94,"2027.M02") -> 1887 | I33: =SUMIFS(Datos!$O$2:$O$94,Datos!$B$2:$B$94,"4064941117254",Datos!$D$2:$D$94,"2027.M03") -> 827 | J33: =SUMIFS(Datos!$O$2:$O$94,Datos!$B$2:$B$94,"4064941117254",Datos!$D$2:$D$94,"2027.M04") -> 327 | K33: =SUM(C33:J33) -> 5527
